Workbook

Sheet Leevi
B3: Parameters | H3: D | I3: E | K3: D | L3: E | M3: S | N3: Cinv | O3: Csf | P3: Ctot | S3: E[Cinv] | T3: E[Csf] | U3: Expected total cost | V3: S
H4: =_xlfn.LOGNORM.INV(RAND(), 1,$D$6) -> 5.8282797 | I4: =H4*_xlfn.LOGNORM.INV(RAND(), 1,$D$7) -> 28.896228 | K4: 9.1908925 | L4: 92.535443 | M4: =$V$4 -> 0 | N4: =M4 -> 0 | O4: =MAX(L4-M4,0)*$C$13 -> 92.535443 | P4: =N4+O4 -> 92.535443 | R4: Low/Low | S4: =AVERAGE(N4:N214) -> 0 | T4: =AVERAGE(O4:O214) -> 398.37616 | U4: =AVERAGE(P4:P214) -> 398.37616 | V4: 0
B5: Uncertainty(standard deviation) | C5: No | D5: Low | E5: Med | F5: High | H5: =_xlfn.LOGNORM.INV(RAND(), 1,$D$6) -> 3.2930444 | I5: =H5*_xlfn.LOGNORM.INV(RAND(), 1,$F$6) -> 0.89043713 | K5: 0.82123037 | L5: 0.029772329 | M5: =$V$4 -> 0 | N5: =M5 -> 0 | O5: =MAX(L5-M5,0)*$C$13 -> 0.029772329 | P5: =N5+O5 -> 0.029772329
C6: 0 | D6: 1 | E6: 2 | F6: 3 | H6: =_xlfn.LOGNORM.INV(RAND(), 1,$D$6) -> 1.0532216 | I6: =H6*_xlfn.LOGNORM.INV(RAND(), 1,$F$6) -> 6.0100192 | K6: 3.0972196 | L6: 1127.3316 | M6: =$V$4 -> 0 | N6: =M6 -> 0 | O6: =MAX(L6-M6,0)*$C$13 -> 1127.3316 | P6: =N6+O6 -> 1127.3316
C7: 0 | D7: 1 | E7: 2 | F7: 3 | H7: =_xlfn.LOGNORM.INV(RAND(), 1,$D$6) -> 2.1087049 | I7: =H7*_xlfn.LOGNORM.INV(RAND(), 1,$F$6) -> 20277.944 | K7: 0.92874821 | L7: 1.2117933 | M7: =$V$4 -> 0 | N7: =M7 -> 0 | O7: =MAX(L7-M7,0)*$C$13 -> 1.2117933 | P7: =N7+O7 -> 1.2117933
H8: =_xlfn.LOGNORM.INV(RAND(), 1,$D$6) -> 3.4421498 | I8: =H8*_xlfn.LOGNORM.INV(RAND(), 1,$F$6) -> 2665.113 | K8: 3.4143272 | L8: 2840.3801 | M8: =$V$4 -> 0 | N8: =M8 -> 0 | O8: =MAX(L8-M8,0)*$C$13 -> 2840.3801 | P8: =N8+O8 -> 2840.3801
B9: D | C9: =D6 -> 1 | H9: =_xlfn.LOGNORM.INV(RAND(), 1,$D$6) -> 5.2143788 | I9: =H9*_xlfn.LOGNORM.INV(RAND(), 1,$F$6) -> 0.33066756 | K9: 2.2311205 | L9: 2.786269 | M9: =$V$4 -> 0 | N9: =M9 -> 0 | O9: =MAX(L9-M9,0)*$C$13 -> 2.786269 | P9: =N9+O9 -> 2.786269
B10: E | C10: =D7 -> 1 | H10: =_xlfn.LOGNORM.INV(RAND(), 1,$D$6) -> 1.1289237 | I10: =H10*_xlfn.LOGNORM.INV(RAND(), 1,$F$6) -> 62.435217 | K10: 6.5741778 | L10: 1335.3147 | M10: =$V$4 -> 0 | N10: =M10 -> 0 | O10: =MAX(L10-M10,0)*$C$13 -> 1335.3147 | P10: =N10+O10 -> 1335.3147
H11: =_xlfn.LOGNORM.INV(RAND(), 1,$D$6) -> 1.9492717 | I11: =H11*_xlfn.LOGNORM.INV(RAND(), 1,$F$6) -> 0.024896841 | K11: 0.52742922 | L11: 4.0367975 | M11: =$V$4 -> 0 | N11: =M11 -> 0 | O11: =MAX(L11-M11,0)*$C$13 -> 4.0367975 | P11: =N11+O11 -> 4.0367975
B12: Other parameters | H12: =_xlfn.LOGNORM.INV(RAND(), 1,$D$6) -> 12.803517 | I12: =H12*_xlfn.LOGNORM.INV(RAND(), 1,$F$6) -> 650.66853 | K12: 5.3815327 | L12: 13.890693 | M12: =$V$4 -> 0 | N12: =M12 -> 0 | O12: =MAX(L12-M12,0)*$C$13 -> 13.890693 | P12: =N12+O12 -> 13.890693
B13: c^s | C13: 1 | H13: =_xlfn.LOGNORM.INV(RAND(), 1,$D$6) -> 1.1627206 | I13: =H13*_xlfn.LOGNORM.INV(RAND(), 1,$F$6) -> 0.098976471 | K13: 0.77134037 | L13: 10.071784 | M13: =$V$4 -> 0 | N13: =M13 -> 0 | O13: =MAX(L13-M13,0)*$C$13 -> 10.071784 | P13: =N13+O13 -> 10.071784
B14: Mean D | C14: =(-C9^2)/2 -> 0.5 | H14: =_xlfn.LOGNORM.INV(RAND(), 1,$D$6) -> 0.73975327 | I14: =H14*_xlfn.LOGNORM.INV(RAND(), 1,$F$6) -> 3.8547197 | K14: 3.1547141 | L14: 0.59434697 | M14: =$V$4 -> 0 | N14: =M14 -> 0 | O14: =MAX(L14-M14,0)*$C$13 -> 0.59434697 | P14: =N14+O14 -> 0.59434697
B15: Mean E | C15: =(-C10^2)/2 -> 0.5 | H15: =_xlfn.LOGNORM.INV(RAND(), 1,$D$6) -> 0.84324058 | I15: =H15*_xlfn.LOGNORM.INV(RAND(), 1,$F$6) -> 0.11576901 | K15: 0.48883394 | L15: 1.2252333 | M15: =$V$4 -> 0 | N15: =M15 -> 0 | O15: =MAX(L15-M15,0)*$C$13 -> 1.2252333 | P15: =N15+O15 -> 1.2252333
H16: =_xlfn.LOGNORM.INV(RAND(), 1,$D$6) -> 3.573354 | I16: =H16*_xlfn.LOGNORM.INV(RAND(), 1,$F$6) -> 0.63311653 | K16: 8.7436687 | L16: 78.378386 | M16: =$V$4 -> 0 | N16: =M16 -> 0 | O16: =MAX(L16-M16,0)*$C$13 -> 78.378386 | P16: =N16+O16 -> 78.378386
H17: =_xlfn.LOGNORM.INV(RAND(), 1,$D$6) -> 3.5508953 | I17: =H17*_xlfn.LOGNORM.INV(RAND(), 1,$F$6) -> 1334.7524 | K17: 34.416485 | L17: 18.501167 | M17: =$V$4 -> 0 | N17: =M17 -> 0 | O17: =MAX(L17-M17,0)*$C$13 -> 18.501167 | P17: =N17+O17 -> 18.501167
H18: =_xlfn.LOGNORM.INV(RAND(), 1,$D$6) -> 1.8042978 | I18: =H18*_xlfn.LOGNORM.INV(RAND(), 1,$F$6) -> 2.4402196 | K18: 33.448858 | L18: 8835.3256 | M18: =$V$4 -> 0 | N18: =M18 -> 0 | O18: =MAX(L18-M18,0)*$C$13 -> 8835.3256 | P18: =N18+O18 -> 8835.3256
H19: =_xlfn.LOGNORM.INV(RAND(), 1,$D$6) -> 2.1529848 | I19: =H19*_xlfn.LOGNORM.INV(RAND(), 1,$F$6) -> 1.2788723 | K19: 2.5240014 | L19: 28.191201 | M19: =$V$4 -> 0 | N19: =M19 -> 0 | O19: =MAX(L19-M19,0)*$C$13 -> 28.191201 | P19: =N19+O19 -> 28.191201
H20: =_xlfn.LOGNORM.INV(RAND(), 1,$D$6) -> 1.7539727 | I20: =H20*_xlfn.LOGNORM.INV(RAND(), 1,$F$6) -> 202.18277 | K20: 13.915903 | L20: 1.4513621 | M20: =$V$4 -> 0 | N20: =M20 -> 0 | O20: =MAX(L20-M20,0)*$C$13 -> 1.4513621 | P20: =N20+O20 -> 1.4513621
H21: =_xlfn.LOGNORM.INV(RAND(), 1,$D$6) -> 5.6141565 | I21: =H21*_xlfn.LOGNORM.INV(RAND(), 1,$F$6) -> 0.86624278 | K21: 1.4736046 | L21: 0.066270571 | M21: =$V$4 -> 0 | N21: =M21 -> 0 | O21: =MAX(L21-M21,0)*$C$13 -> 0.066270571 | P21: =N21+O21 -> 0.066270571
H22: =_xlfn.LOGNORM.INV(RAND(), 1,$D$6) -> 1.1854889 | I22: =H22*_xlfn.LOGNORM.INV(RAND(), 1,$F$6) -> 1.0365785 | K22: 0.93345294 | L22: 0.20937872 | M22: =$V$4 -> 0 | N22: =M22 -> 0 | O22: =MAX(L22-M22,0)*$C$13 -> 0.20937872 | P22: =N22+O22 -> 0.20937872
H23: =_xlfn.LOGNORM.INV(RAND(), 1,$D$6) -> 1.5189459 | I23: =H23*_xlfn.LOGNORM.INV(RAND(), 1,$F$6) -> 1516.4818 | K23: 1.5448926 | L23: 140.21408 | M23: =$V$4 -> 0 | N23: =M23 -> 0 | O23: =MAX(L23-M23,0)*$C$13 -> 140.21408 | P23: =N23+O23 -> 140.21408
H24: =_xlfn.LOGNORM.INV(RAND(), 1,$D$6) -> 5.0874586 | I24: =H24*_xlfn.LOGNORM.INV(RAND(), 1,$F$6) -> 4.2543448 | K24: 10.528578 | L24: 2696.0866 | M24: =$V$4 -> 0 | N24: =M24 -> 0 | O24: =MAX(L24-M24,0)*$C$13 -> 2696.0866 | P24: =N24+O24 -> 2696.0866
H25: =_xlfn.LOGNORM.INV(RAND(), 1,$D$6) -> 11.148234 | I25: =H25*_xlfn.LOGNORM.INV(RAND(), 1,$F$6) -> 4472.1429 | K25: 3.6935525 | L25: 1.0063342 | M25: =$V$4 -> 0 | N25: =M25 -> 0 | O25: =MAX(L25-M25,0)*$C$13 -> 1.0063342 | P25: =N25+O25 -> 1.0063342
H26: =_xlfn.LOGNORM.INV(RAND(), 1,$D$6) -> 2.3948582 | I26: =H26*_xlfn.LOGNORM.INV(RAND(), 1,$F$6) -> 97.205521 | K26: 0.71476766 | L26: 0.13151015 | M26: =$V$4 -> 0 | N26: =M26 -> 0 | O26: =MAX(L26-M26,0)*$C$13 -> 0.13151015 | P26: =N26+O26 -> 0.13151015
H27: =_xlfn.LOGNORM.INV(RAND(), 1,$D$6) -> 1.8119037 | I27: =H27*_xlfn.LOGNORM.INV(RAND(), 1,$F$6) -> 198.47903 | K27: 2.6907113 | L27: 1.4435237 | M27: =$V$4 -> 0 | N27: =M27 -> 0 | O27: =MAX(L27-M27,0)*$C$13 -> 1.4435237 | P27: =N27+O27 -> 1.4435237
... H214: =_xlfn.LOGNORM.INV(RAND(), 1,$D$6) -> 1.9016312 | I214: =H214*_xlfn.LOGNORM.INV(RAND(), 1,$F$6) -> 7.0475778 | K214: 4.5688582 | L214: 81.784067 | M214: =$V$4 -> 0 | N214: =M214 -> 0 | O214: =MAX(L214-M214,0)*$C$13 -> 81.784067 | P214: =N214+O214 -> 81.784067

Sheet Summary
C3: Expected total cost | K3: S/Cinv | R3: Cesf
E4: High | F4: =HiNo!$R$3 -> 3.0536997 | G4: =HiLo!$R$3 -> 3.3291294 | H4: =HiMe!$R$3 -> 3.635342 | I4: =HiHi!$R$3 -> 5.4864977 | L4: High | M4: =HiNo!$L$3 -> 2.4017505 | N4: =HiLo!$L$3 -> 2.3113656 | O4: =HiMe!$L$3 -> 1.6775859 | P4: =HiHi!$L$3 -> 1.9449569 | S4: High | T4: =HiNo!$Q$3 -> 0.65194918 | U4: =HiLo!$Q$3 -> 1.0177638 | V4: =HiMe!$Q$3 -> 1.957756 | W4: =HiHi!$Q$3 -> 3.5415408
E5: Med | F5: =MeNo!$R$3 -> 1.78342 | G5: =MeLo!$R$3 -> 2.4143512 | H5: =MeMe!$R$3 -> 2.5198364 | I5: =MeHi!$R$3 -> 3.6104551 | L5: Med | M5: =MeNo!$L$3 -> 1.1583175 | N5: =MeLo!$L$3 -> 2.2220516 | O5: =MeMe!$L$3 -> 1.865441 | P5: =MeHi!$L$3 -> 1.7597175 | S5: Med | T5: =MeNo!$Q$3 -> 0.62510252 | U5: =MeLo!$Q$3 -> 0.19229961 | V5: =MeMe!$Q$3 -> 0.65439546 | W5: =MeHi!$Q$3 -> 1.8507376
E6: Low | F6: =LoNo!$R$3 -> 1.2924135 | G6: =LoLo!$R$3 -> 1.5202651 | H6: =LoMe!$R$3 -> 2.2458538 | I6: =LoHi!$R$3 -> 3.0972341 | L6: Low | M6: =LoNo!$L$3 -> 0.97322576 | N6: =LoLo!$L$3 -> 1.3547706 | O6: =LoMe!$L$3 -> 2.0179267 | P6: =LoHi!$L$3 -> 1.8638923 | S6: Low | T6: =LoNo!$LQ3 -> 0 | U6: =LoLo!$Q$3 -> 0.16549448 | V6: =LoMe!$Q$3 -> 0.22792705 | W6: =LoHi!$Q$3 -> 1.2333417
E7: None | F7: =NoNo!$R$3 -> 1 | G7: =NoLo!$R$3 -> 1.414291 | H7: =NoMe!$R$3 -> 2.2534836 | I7: =NoHi!$R$3 -> 2.7610312 | L7: None | M7: =NoNo!$L$3 -> 1 | N7: =NoLo!$L$3 -> 1.3633031 | O7: =NoMe!$L$3 -> 2.1125897 | P7: =NoHi!$L$3 -> 1.9105839 | S7: None | T7: =NoNo!$Q$3 -> 0 | U7: =NoLo!$Q$3 -> 0.050987897 | V7: =NoMe!$Q$3 -> 0.14089388 | W7: =NoHi!$Q$3 -> 0.85044738
F8: None | G8: Low | H8: Med | I8: High | M8: None | N8: Low | O8: Med | P8: High | T8: None | U8: Low | V8: Med | W8: High

Sheet Model
B2: Parameters | H2: D | I2: E | K2: S | L2: Cinv | M2: Cesf | N2: Ctot | P2: E[Cinv] | Q2: E[Cesf] | R2: E[Ctot] | S2: S
H3: =IF($B$8=0, EXP($C$13), _xlfn.LOGNORM.INV(RAND(), $C$13, $B$8)) -> 1 | I3: =IF($B$9=0, EXP($C$14), _xlfn.LOGNORM.INV(RAND(), $C$14, $B$9))*H3 -> 1 | K3: =$S$3 -> 1 | L3: =K3 -> 1 | M3: =$C$12*MAX(I3-K3,0) -> 0 | N3: =M3+L3 -> 1 | P3: =AVERAGE(L3:L1000) -> 1 | Q3: =AVERAGE(M3:M1000) -> 0 | R3: =AVERAGE(N3:N1000) -> 1 | S3: 1
B4: Uncertainty(standard deviation) | C4: No | D4: Low | E4: Med | F4: High | H4: =IF($B$8=0, EXP($C$13), _xlfn.LOGNORM.INV(RAND(), $C$13, $B$8)) -> 1 | I4: =IF($B$9=0, EXP($C$14), _xlfn.LOGNORM.INV(RAND(), $C$14, $B$9))*H4 -> 1 | K4: =$S$3 -> 1 | L4: =K4 -> 1 | M4: =$C$12*MAX(I4-K4,0) -> 0 | N4: =M4+L4 -> 1
C5: 0 | D5: 0.25 | E5: 0.5 | F5: 0.75 | H5: =IF($B$8=0, EXP($C$13), _xlfn.LOGNORM.INV(RAND(), $C$13, $B$8)) -> 1 | I5: =IF($B$9=0, EXP($C$14), _xlfn.LOGNORM.INV(RAND(), $C$14, $B$9))*H5 -> 1 | K5: =$S$3 -> 1 | L5: =K5 -> 1 | M5: =$C$12*MAX(I5-K5,0) -> 0 | N5: =M5+L5 -> 1
C6: 0 | D6: 0.25 | E6: 0.5 | F6: 0.75 | H6: =IF($B$8=0, EXP($C$13), _xlfn.LOGNORM.INV(RAND(), $C$13, $B$8)) -> 1 | I6: =IF($B$9=0, EXP($C$14), _xlfn.LOGNORM.INV(RAND(), $C$14, $B$9))*H6 -> 1 | K6: =$S$3 -> 1 | L6: =K6 -> 1 | M6: =$C$12*MAX(I6-K6,0) -> 0 | N6: =M6+L6 -> 1
H7: =IF($B$8=0, EXP($C$13), _xlfn.LOGNORM.INV(RAND(), $C$13, $B$8)) -> 1 | I7: =IF($B$9=0, EXP($C$14), _xlfn.LOGNORM.INV(RAND(), $C$14, $B$9))*H7 -> 1 | K7: =$S$3 -> 1 | L7: =K7 -> 1 | M7: =$C$12*MAX(I7-K7,0) -> 0 | N7: =M7+L7 -> 1
B8: =C5 -> 0 | C8: Current D uncertianty | H8: =IF($B$8=0, EXP($C$13), _xlfn.LOGNORM.INV(RAND(), $C$13, $B$8)) -> 1 | I8: =IF($B$9=0, EXP($C$14), _xlfn.LOGNORM.INV(RAND(), $C$14, $B$9))*H8 -> 1 | K8: =$S$3 -> 1 | L8: =K8 -> 1 | M8: =$C$12*MAX(I8-K8,0) -> 0 | N8: =M8+L8 -> 1
B9: =C6 -> 0 | C9: Current E uncertainty | H9: =IF($B$8=0, EXP($C$13), _xlfn.LOGNORM.INV(RAND(), $C$13, $B$8)) -> 1 | I9: =IF($B$9=0, EXP($C$14), _xlfn.LOGNORM.INV(RAND(), $C$14, $B$9))*H9 -> 1 | K9: =$S$3 -> 1 | L9: =K9 -> 1 | M9: =$C$12*MAX(I9-K9,0) -> 0 | N9: =M9+L9 -> 1
H10: =IF($B$8=0, EXP($C$13), _xlfn.LOGNORM.INV(RAND(), $C$13, $B$8)) -> 1 | I10: =IF($B$9=0, EXP($C$14), _xlfn.LOGNORM.INV(RAND(), $C$14, $B$9))*H10 -> 1 | K10: =$S$3 -> 1 | L10: =K10 -> 1 | M10: =$C$12*MAX(I10-K10,0) -> 0 | N10: =M10+L10 -> 1
B11: Other parameters | H11: =IF($B$8=0, EXP($C$13), _xlfn.LOGNORM.INV(RAND(), $C$13, $B$8)) -> 1 | I11: =IF($B$9=0, EXP($C$14), _xlfn.LOGNORM.INV(RAND(), $C$14, $B$9))*H11 -> 1 | K11: =$S$3 -> 1 | L11: =K11 -> 1 | M11: =$C$12*MAX(I11-K11,0) -> 0 | N11: =M11+L11 -> 1
B12: c^s | C12: 2 | H12: =IF($B$8=0, EXP($C$13), _xlfn.LOGNORM.INV(RAND(), $C$13, $B$8)) -> 1 | I12: =IF($B$9=0, EXP($C$14), _xlfn.LOGNORM.INV(RAND(), $C$14, $B$9))*H12 -> 1 | K12: =$S$3 -> 1 | L12: =K12 -> 1 | M12: =$C$12*MAX(I12-K12,0) -> 0 | N12: =M12+L12 -> 1
B13: Mean D | C13: =(-B8^2)/2 -> 0 | H13: =IF($B$8=0, EXP($C$13), _xlfn.LOGNORM.INV(RAND(), $C$13, $B$8)) -> 1 | I13: =IF($B$9=0, EXP($C$14), _xlfn.LOGNORM.INV(RAND(), $C$14, $B$9))*H13 -> 1 | K13: =$S$3 -> 1 | L13: =K13 -> 1 | M13: =$C$12*MAX(I13-K13,0) -> 0 | N13: =M13+L13 -> 1
B14: Mean E | C14: =(-B9^2)/2 -> 0 | H14: =IF($B$8=0, EXP($C$13), _xlfn.LOGNORM.INV(RAND(), $C$13, $B$8)) -> 1 | I14: =IF($B$9=0, EXP($C$14), _xlfn.LOGNORM.INV(RAND(), $C$14, $B$9))*H14 -> 1 | K14: =$S$3 -> 1 | L14: =K14 -> 1 | M14: =$C$12*MAX(I14-K14,0) -> 0 | N14: =M14+L14 -> 1
H15: =IF($B$8=0, EXP($C$13), _xlfn.LOGNORM.INV(RAND(), $C$13, $B$8)) -> 1 | I15: =IF($B$9=0, EXP($C$14), _xlfn.LOGNORM.INV(RAND(), $C$14, $B$9))*H15 -> 1 | K15: =$S$3 -> 1 | L15: =K15 -> 1 | M15: =$C$12*MAX(I15-K15,0) -> 0 | N15: =M15+L15 -> 1
H16: =IF($B$8=0, EXP($C$13), _xlfn.LOGNORM.INV(RAND(), $C$13, $B$8)) -> 1 | I16: =IF($B$9=0, EXP($C$14), _xlfn.LOGNORM.INV(RAND(), $C$14, $B$9))*H16 -> 1 | K16: =$S$3 -> 1 | L16: =K16 -> 1 | M16: =$C$12*MAX(I16-K16,0) -> 0 | N16: =M16+L16 -> 1
H17: =IF($B$8=0, EXP($C$13), _xlfn.LOGNORM.INV(RAND(), $C$13, $B$8)) -> 1 | I17: =IF($B$9=0, EXP($C$14), _xlfn.LOGNORM.INV(RAND(), $C$14, $B$9))*H17 -> 1 | K17: =$S$3 -> 1 | L17: =K17 -> 1 | M17: =$C$12*MAX(I17-K17,0) -> 0 | N17: =M17+L17 -> 1
H18: =IF($B$8=0, EXP($C$13), _xlfn.LOGNORM.INV(RAND(), $C$13, $B$8)) -> 1 | I18: =IF($B$9=0, EXP($C$14), _xlfn.LOGNORM.INV(RAND(), $C$14, $B$9))*H18 -> 1 | K18: =$S$3 -> 1 | L18: =K18 -> 1 | M18: =$C$12*MAX(I18-K18,0) -> 0 | N18: =M18+L18 -> 1
H19: =IF($B$8=0, EXP($C$13), _xlfn.LOGNORM.INV(RAND(), $C$13, $B$8)) -> 1 | I19: =IF($B$9=0, EXP($C$14), _xlfn.LOGNORM.INV(RAND(), $C$14, $B$9))*H19 -> 1 | K19: =$S$3 -> 1 | L19: =K19 -> 1 | M19: =$C$12*MAX(I19-K19,0) -> 0 | N19: =M19+L19 -> 1
H20: =IF($B$8=0, EXP($C$13), _xlfn.LOGNORM.INV(RAND(), $C$13, $B$8)) -> 1 | I20: =IF($B$9=0, EXP($C$14), _xlfn.LOGNORM.INV(RAND(), $C$14, $B$9))*H20 -> 1 | K20: =$S$3 -> 1 | L20: =K20 -> 1 | M20: =$C$12*MAX(I20-K20,0) -> 0 | N20: =M20+L20 -> 1
H21: =IF($B$8=0, EXP($C$13), _xlfn.LOGNORM.INV(RAND(), $C$13, $B$8)) -> 1 | I21: =IF($B$9=0, EXP($C$14), _xlfn.LOGNORM.INV(RAND(), $C$14, $B$9))*H21 -> 1 | K21: =$S$3 -> 1 | L21: =K21 -> 1 | M21: =$C$12*MAX(I21-K21,0) -> 0 | N21: =M21+L21 -> 1
H22: =IF($B$8=0, EXP($C$13), _xlfn.LOGNORM.INV(RAND(), $C$13, $B$8)) -> 1 | I22: =IF($B$9=0, EXP($C$14), _xlfn.LOGNORM.INV(RAND(), $C$14, $B$9))*H22 -> 1 | K22: =$S$3 -> 1 | L22: =K22 -> 1 | M22: =$C$12*MAX(I22-K22,0) -> 0 | N22: =M22+L22 -> 1
H23: =IF($B$8=0, EXP($C$13), _xlfn.LOGNORM.INV(RAND(), $C$13, $B$8)) -> 1 | I23: =IF($B$9=0, EXP($C$14), _xlfn.LOGNORM.INV(RAND(), $C$14, $B$9))*H23 -> 1 | K23: =$S$3 -> 1 | L23: =K23 -> 1 | M23: =$C$12*MAX(I23-K23,0) -> 0 | N23: =M23+L23 -> 1
H24: =IF($B$8=0, EXP($C$13), _xlfn.LOGNORM.INV(RAND(), $C$13, $B$8)) -> 1 | I24: =IF($B$9=0, EXP($C$14), _xlfn.LOGNORM.INV(RAND(), $C$14, $B$9))*H24 -> 1 | K24: =$S$3 -> 1 | L24: =K24 -> 1 | M24: =$C$12*MAX(I24-K24,0) -> 0 | N24: =M24+L24 -> 1
H25: =IF($B$8=0, EXP($C$13), _xlfn.LOGNORM.INV(RAND(), $C$13, $B$8)) -> 1 | I25: =IF($B$9=0, EXP($C$14), _xlfn.LOGNORM.INV(RAND(), $C$14, $B$9))*H25 -> 1 | K25: =$S$3 -> 1 | L25: =K25 -> 1 | M25: =$C$12*MAX(I25-K25,0) -> 0 | N25: =M25+L25 -> 1
H26: =IF($B$8=0, EXP($C$13), _xlfn.LOGNORM.INV(RAND(), $C$13, $B$8)) -> 1 | I26: =IF($B$9=0, EXP($C$14), _xlfn.LOGNORM.INV(RAND(), $C$14, $B$9))*H26 -> 1 | K26: =$S$3 -> 1 | L26: =K26 -> 1 | M26: =$C$12*MAX(I26-K26,0) -> 0 | N26: =M26+L26 -> 1
... H1000: =IF($B$8=0, EXP($C$13), _xlfn.LOGNORM.INV(RAND(), $C$13, $B$8)) -> 1 | I1000: =IF($B$9=0, EXP($C$14), _xlfn.LOGNORM.INV(RAND(), $C$14, $B$9))*H1000 -> 1 | K1000: =$S$3 -> 1 | L1000: =K1000 -> 1 | M1000: =$C$12*MAX(I1000-K1000,0) -> 0 | N1000: =M1000+L1000 -> 1

Sheet NoNo
B2: Parameters | H2: D | I2: E | K2: S | L2: Cinv | M2: Cesf | N2: Ctot | P2: E[Cinv] | Q2: E[Cesf] | R2: E[Ctot] | S2: S
H3: =IF($B$8=0, EXP($C$13), _xlfn.LOGNORM.INV(RAND(), $C$13, $B$8)) -> 1 | I3: =IF($B$9=0, EXP($C$14), _xlfn.LOGNORM.INV(RAND(), $C$14, $B$9))*H3 -> 1 | K3: =$S$3 -> 1 | L3: =K3 -> 1 | M3: =$C$12*MAX(I3-K3,0) -> 0 | N3: =M3+L3 -> 1 | P3: =AVERAGE(L3:L1000) -> 1 | Q3: =AVERAGE(M3:M1000) -> 0 | R3: =AVERAGE(N3:N1000) -> 1 | S3: 1
B4: Uncertainty(standard deviation) | C4: No | D4: Low | E4: Med | F4: High | H4: =IF($B$8=0, EXP($C$13), _xlfn.LOGNORM.INV(RAND(), $C$13, $B$8)) -> 1 | I4: =IF($B$9=0, EXP($C$14), _xlfn.LOGNORM.INV(RAND(), $C$14, $B$9))*H4 -> 1 | K4: =$S$3 -> 1 | L4: =K4 -> 1 | M4: =$C$12*MAX(I4-K4,0) -> 0 | N4: =M4+L4 -> 1
C5: 0 | D5: 0.25 | E5: 0.5 | F5: 0.75 | H5: =IF($B$8=0, EXP($C$13), _xlfn.LOGNORM.INV(RAND(), $C$13, $B$8)) -> 1 | I5: =IF($B$9=0, EXP($C$14), _xlfn.LOGNORM.INV(RAND(), $C$14, $B$9))*H5 -> 1 | K5: =$S$3 -> 1 | L5: =K5 -> 1 | M5: =$C$12*MAX(I5-K5,0) -> 0 | N5: =M5+L5 -> 1
C6: 0 | D6: 0.25 | E6: 0.5 | F6: 0.75 | H6: =IF($B$8=0, EXP($C$13), _xlfn.LOGNORM.INV(RAND(), $C$13, $B$8)) -> 1 | I6: =IF($B$9=0, EXP($C$14), _xlfn.LOGNORM.INV(RAND(), $C$14, $B$9))*H6 -> 1 | K6: =$S$3 -> 1 | L6: =K6 -> 1 | M6: =$C$12*MAX(I6-K6,0) -> 0 | N6: =M6+L6 -> 1
H7: =IF($B$8=0, EXP($C$13), _xlfn.LOGNORM.INV(RAND(), $C$13, $B$8)) -> 1 | I7: =IF($B$9=0, EXP($C$14), _xlfn.LOGNORM.INV(RAND(), $C$14, $B$9))*H7 -> 1 | K7: =$S$3 -> 1 | L7: =K7 -> 1 | M7: =$C$12*MAX(I7-K7,0) -> 0 | N7: =M7+L7 -> 1
B8: =C5 -> 0 | C8: Current D uncertianty | H8: =IF($B$8=0, EXP($C$13), _xlfn.LOGNORM.INV(RAND(), $C$13, $B$8)) -> 1 | I8: =IF($B$9=0, EXP($C$14), _xlfn.LOGNORM.INV(RAND(), $C$14, $B$9))*H8 -> 1 | K8: =$S$3 -> 1 | L8: =K8 -> 1 | M8: =$C$12*MAX(I8-K8,0) -> 0 | N8: =M8+L8 -> 1
B9: =C6 -> 0 | C9: Current E uncertainty | H9: =IF($B$8=0, EXP($C$13), _xlfn.LOGNORM.INV(RAND(), $C$13, $B$8)) -> 1 | I9: =IF($B$9=0, EXP($C$14), _xlfn.LOGNORM.INV(RAND(), $C$14, $B$9))*H9 -> 1 | K9: =$S$3 -> 1 | L9: =K9 -> 1 | M9: =$C$12*MAX(I9-K9,0) -> 0 | N9: =M9+L9 -> 1
H10: =IF($B$8=0, EXP($C$13), _xlfn.LOGNORM.INV(RAND(), $C$13, $B$8)) -> 1 | I10: =IF($B$9=0, EXP($C$14), _xlfn.LOGNORM.INV(RAND(), $C$14, $B$9))*H10 -> 1 | K10: =$S$3 -> 1 | L10: =K10 -> 1 | M10: =$C$12*MAX(I10-K10,0) -> 0 | N10: =M10+L10 -> 1
B11: Other parameters | H11: =IF($B$8=0, EXP($C$13), _xlfn.LOGNORM.INV(RAND(), $C$13, $B$8)) -> 1 | I11: =IF($B$9=0, EXP($C$14), _xlfn.LOGNORM.INV(RAND(), $C$14, $B$9))*H11 -> 1 | K11: =$S$3 -> 1 | L11: =K11 -> 1 | M11: =$C$12*MAX(I11-K11,0) -> 0 | N11: =M11+L11 -> 1
B12: c^s | C12: =Model!C12 -> 2 | H12: =IF($B$8=0, EXP($C$13), _xlfn.LOGNORM.INV(RAND(), $C$13, $B$8)) -> 1 | I12: =IF($B$9=0, EXP($C$14), _xlfn.LOGNORM.INV(RAND(), $C$14, $B$9))*H12 -> 1 | K12: =$S$3 -> 1 | L12: =K12 -> 1 | M12: =$C$12*MAX(I12-K12,0) -> 0 | N12: =M12+L12 -> 1
B13: Mean D | C13: =(-B8^2)/2 -> 0 | H13: =IF($B$8=0, EXP($C$13), _xlfn.LOGNORM.INV(RAND(), $C$13, $B$8)) -> 1 | I13: =IF($B$9=0, EXP($C$14), _xlfn.LOGNORM.INV(RAND(), $C$14, $B$9))*H13 -> 1 | K13: =$S$3 -> 1 | L13: =K13 -> 1 | M13: =$C$12*MAX(I13-K13,0) -> 0 | N13: =M13+L13 -> 1
B14: Mean E | C14: =(-B9^2)/2 -> 0 | H14: =IF($B$8=0, EXP($C$13), _xlfn.LOGNORM.INV(RAND(), $C$13, $B$8)) -> 1 | I14: =IF($B$9=0, EXP($C$14), _xlfn.LOGNORM.INV(RAND(), $C$14, $B$9))*H14 -> 1 | K14: =$S$3 -> 1 | L14: =K14 -> 1 | M14: =$C$12*MAX(I14-K14,0) -> 0 | N14: =M14+L14 -> 1
H15: =IF($B$8=0, EXP($C$13), _xlfn.LOGNORM.INV(RAND(), $C$13, $B$8)) -> 1 | I15: =IF($B$9=0, EXP($C$14), _xlfn.LOGNORM.INV(RAND(), $C$14, $B$9))*H15 -> 1 | K15: =$S$3 -> 1 | L15: =K15 -> 1 | M15: =$C$12*MAX(I15-K15,0) -> 0 | N15: =M15+L15 -> 1
H16: =IF($B$8=0, EXP($C$13), _xlfn.LOGNORM.INV(RAND(), $C$13, $B$8)) -> 1 | I16: =IF($B$9=0, EXP($C$14), _xlfn.LOGNORM.INV(RAND(), $C$14, $B$9))*H16 -> 1 | K16: =$S$3 -> 1 | L16: =K16 -> 1 | M16: =$C$12*MAX(I16-K16,0) -> 0 | N16: =M16+L16 -> 1
H17: =IF($B$8=0, EXP($C$13), _xlfn.LOGNORM.INV(RAND(), $C$13, $B$8)) -> 1 | I17: =IF($B$9=0, EXP($C$14), _xlfn.LOGNORM.INV(RAND(), $C$14, $B$9))*H17 -> 1 | K17: =$S$3 -> 1 | L17: =K17 -> 1 | M17: =$C$12*MAX(I17-K17,0) -> 0 | N17: =M17+L17 -> 1
H18: =IF($B$8=0, EXP($C$13), _xlfn.LOGNORM.INV(RAND(), $C$13, $B$8)) -> 1 | I18: =IF($B$9=0, EXP($C$14), _xlfn.LOGNORM.INV(RAND(), $C$14, $B$9))*H18 -> 1 | K18: =$S$3 -> 1 | L18: =K18 -> 1 | M18: =$C$12*MAX(I18-K18,0) -> 0 | N18: =M18+L18 -> 1
H19: =IF($B$8=0, EXP($C$13), _xlfn.LOGNORM.INV(RAND(), $C$13, $B$8)) -> 1 | I19: =IF($B$9=0, EXP($C$14), _xlfn.LOGNORM.INV(RAND(), $C$14, $B$9))*H19 -> 1 | K19: =$S$3 -> 1 | L19: =K19 -> 1 | M19: =$C$12*MAX(I19-K19,0) -> 0 | N19: =M19+L19 -> 1
H20: =IF($B$8=0, EXP($C$13), _xlfn.LOGNORM.INV(RAND(), $C$13, $B$8)) -> 1 | I20: =IF($B$9=0, EXP($C$14), _xlfn.LOGNORM.INV(RAND(), $C$14, $B$9))*H20 -> 1 | K20: =$S$3 -> 1 | L20: =K20 -> 1 | M20: =$C$12*MAX(I20-K20,0) -> 0 | N20: =M20+L20 -> 1
H21: =IF($B$8=0, EXP($C$13), _xlfn.LOGNORM.INV(RAND(), $C$13, $B$8)) -> 1 | I21: =IF($B$9=0, EXP($C$14), _xlfn.LOGNORM.INV(RAND(), $C$14, $B$9))*H21 -> 1 | K21: =$S$3 -> 1 | L21: =K21 -> 1 | M21: =$C$12*MAX(I21-K21,0) -> 0 | N21: =M21+L21 -> 1
H22: =IF($B$8=0, EXP($C$13), _xlfn.LOGNORM.INV(RAND(), $C$13, $B$8)) -> 1 | I22: =IF($B$9=0, EXP($C$14), _xlfn.LOGNORM.INV(RAND(), $C$14, $B$9))*H22 -> 1 | K22: =$S$3 -> 1 | L22: =K22 -> 1 | M22: =$C$12*MAX(I22-K22,0) -> 0 | N22: =M22+L22 -> 1
H23: =IF($B$8=0, EXP($C$13), _xlfn.LOGNORM.INV(RAND(), $C$13, $B$8)) -> 1 | I23: =IF($B$9=0, EXP($C$14), _xlfn.LOGNORM.INV(RAND(), $C$14, $B$9))*H23 -> 1 | K23: =$S$3 -> 1 | L23: =K23 -> 1 | M23: =$C$12*MAX(I23-K23,0) -> 0 | N23: =M23+L23 -> 1
H24: =IF($B$8=0, EXP($C$13), _xlfn.LOGNORM.INV(RAND(), $C$13, $B$8)) -> 1 | I24: =IF($B$9=0, EXP($C$14), _xlfn.LOGNORM.INV(RAND(), $C$14, $B$9))*H24 -> 1 | K24: =$S$3 -> 1 | L24: =K24 -> 1 | M24: =$C$12*MAX(I24-K24,0) -> 0 | N24: =M24+L24 -> 1
H25: =IF($B$8=0, EXP($C$13), _xlfn.LOGNORM.INV(RAND(), $C$13, $B$8)) -> 1 | I25: =IF($B$9=0, EXP($C$14), _xlfn.LOGNORM.INV(RAND(), $C$14, $B$9))*H25 -> 1 | K25: =$S$3 -> 1 | L25: =K25 -> 1 | M25: =$C$12*MAX(I25-K25,0) -> 0 | N25: =M25+L25 -> 1
H26: =IF($B$8=0, EXP($C$13), _xlfn.LOGNORM.INV(RAND(), $C$13, $B$8)) -> 1 | I26: =IF($B$9=0, EXP($C$14), _xlfn.LOGNORM.INV(RAND(), $C$14, $B$9))*H26 -> 1 | K26: =$S$3 -> 1 | L26: =K26 -> 1 | M26: =$C$12*MAX(I26-K26,0) -> 0 | N26: =M26+L26 -> 1
... H1000: =IF($B$8=0, EXP($C$13), _xlfn.LOGNORM.INV(RAND(), $C$13, $B$8)) -> 1 | I1000: =IF($B$9=0, EXP($C$14), _xlfn.LOGNORM.INV(RAND(), $C$14, $B$9))*H1000 -> 1 | K1000: =$S$3 -> 1 | L1000: =K1000 -> 1 | M1000: =$C$12*MAX(I1000-K1000,0) -> 0 | N1000: =M1000+L1000 -> 1

Sheet LoNo
B2: Parameters | H2: D | I2: E | K2: S | L2: Cinv | M2: Cesf | N2: Ctot | P2: E[Cinv] | Q2: E[Cesf] | R2: E[Ctot] | S2: S
H3: =IF($B$8=0, EXP($C$13), _xlfn.LOGNORM.INV(RAND(), $C$13, $B$8)) -> 0.85356723 | I3: =IF($B$9=0, EXP($C$14), _xlfn.LOGNORM.INV(RAND(), $C$14, $B$9))*H3 -> 0.85356723 | K3: =$S$3 -> 0.97322576 | L3: =K3 -> 0.97322576 | M3: =$C$12*MAX(I3-K3,0) -> 0 | N3: =M3+L3 -> 0.97322576 | P3: =AVERAGE(L3:L1000) -> 0.97322576 | Q3: =AVERAGE(M3:M1000) -> 0.31918773 | R3: =AVERAGE(N3:N1000) -> 1.2924135 | S3: 0.97322576
B4: Uncertainty(standard deviation) | C4: No | D4: Low | E4: Med | F4: High | H4: =IF($B$8=0, EXP($C$13), _xlfn.LOGNORM.INV(RAND(), $C$13, $B$8)) -> 0.85708116 | I4: =IF($B$9=0, EXP($C$14), _xlfn.LOGNORM.INV(RAND(), $C$14, $B$9))*H4 -> 0.85708116 | K4: =$S$3 -> 0.97322576 | L4: =K4 -> 0.97322576 | M4: =$C$12*MAX(I4-K4,0) -> 0 | N4: =M4+L4 -> 0.97322576
C5: 0 | D5: 0.25 | E5: 0.5 | F5: 0.75 | H5: =IF($B$8=0, EXP($C$13), _xlfn.LOGNORM.INV(RAND(), $C$13, $B$8)) -> 0.76466645 | I5: =IF($B$9=0, EXP($C$14), _xlfn.LOGNORM.INV(RAND(), $C$14, $B$9))*H5 -> 0.76466645 | K5: =$S$3 -> 0.97322576 | L5: =K5 -> 0.97322576 | M5: =$C$12*MAX(I5-K5,0) -> 0 | N5: =M5+L5 -> 0.97322576
C6: 0 | D6: 0.25 | E6: 0.5 | F6: 0.75 | H6: =IF($B$8=0, EXP($C$13), _xlfn.LOGNORM.INV(RAND(), $C$13, $B$8)) -> 1.3032231 | I6: =IF($B$9=0, EXP($C$14), _xlfn.LOGNORM.INV(RAND(), $C$14, $B$9))*H6 -> 1.3032231 | K6: =$S$3 -> 0.97322576 | L6: =K6 -> 0.97322576 | M6: =$C$12*MAX(I6-K6,0) -> 0.65999472 | N6: =M6+L6 -> 1.6332205
H7: =IF($B$8=0, EXP($C$13), _xlfn.LOGNORM.INV(RAND(), $C$13, $B$8)) -> 1.2603385 | I7: =IF($B$9=0, EXP($C$14), _xlfn.LOGNORM.INV(RAND(), $C$14, $B$9))*H7 -> 1.2603385 | K7: =$S$3 -> 0.97322576 | L7: =K7 -> 0.97322576 | M7: =$C$12*MAX(I7-K7,0) -> 0.57422542 | N7: =M7+L7 -> 1.5474512
B8: =D5 -> 0.25 | C8: Current D uncertianty | H8: =IF($B$8=0, EXP($C$13), _xlfn.LOGNORM.INV(RAND(), $C$13, $B$8)) -> 1.2580561 | I8: =IF($B$9=0, EXP($C$14), _xlfn.LOGNORM.INV(RAND(), $C$14, $B$9))*H8 -> 1.2580561 | K8: =$S$3 -> 0.97322576 | L8: =K8 -> 0.97322576 | M8: =$C$12*MAX(I8-K8,0) -> 0.56966069 | N8: =M8+L8 -> 1.5428864
B9: =C6 -> 0 | C9: Current E uncertainty | H9: =IF($B$8=0, EXP($C$13), _xlfn.LOGNORM.INV(RAND(), $C$13, $B$8)) -> 0.91127225 | I9: =IF($B$9=0, EXP($C$14), _xlfn.LOGNORM.INV(RAND(), $C$14, $B$9))*H9 -> 0.91127225 | K9: =$S$3 -> 0.97322576 | L9: =K9 -> 0.97322576 | M9: =$C$12*MAX(I9-K9,0) -> 0 | N9: =M9+L9 -> 0.97322576
H10: =IF($B$8=0, EXP($C$13), _xlfn.LOGNORM.INV(RAND(), $C$13, $B$8)) -> 1.2916611 | I10: =IF($B$9=0, EXP($C$14), _xlfn.LOGNORM.INV(RAND(), $C$14, $B$9))*H10 -> 1.2916611 | K10: =$S$3 -> 0.97322576 | L10: =K10 -> 0.97322576 | M10: =$C$12*MAX(I10-K10,0) -> 0.63687073 | N10: =M10+L10 -> 1.6100965
B11: Other parameters | H11: =IF($B$8=0, EXP($C$13), _xlfn.LOGNORM.INV(RAND(), $C$13, $B$8)) -> 1.323414 | I11: =IF($B$9=0, EXP($C$14), _xlfn.LOGNORM.INV(RAND(), $C$14, $B$9))*H11 -> 1.323414 | K11: =$S$3 -> 0.97322576 | L11: =K11 -> 0.97322576 | M11: =$C$12*MAX(I11-K11,0) -> 0.70037654 | N11: =M11+L11 -> 1.6736023
B12: c^s | C12: =Model!C12 -> 2 | H12: =IF($B$8=0, EXP($C$13), _xlfn.LOGNORM.INV(RAND(), $C$13, $B$8)) -> 0.92089834 | I12: =IF($B$9=0, EXP($C$14), _xlfn.LOGNORM.INV(RAND(), $C$14, $B$9))*H12 -> 0.92089834 | K12: =$S$3 -> 0.97322576 | L12: =K12 -> 0.97322576 | M12: =$C$12*MAX(I12-K12,0) -> 0 | N12: =M12+L12 -> 0.97322576
B13: Mean D | C13: =(-B8^2)/2 -> 0.03125 | H13: =IF($B$8=0, EXP($C$13), _xlfn.LOGNORM.INV(RAND(), $C$13, $B$8)) -> 1.1319502 | I13: =IF($B$9=0, EXP($C$14), _xlfn.LOGNORM.INV(RAND(), $C$14, $B$9))*H13 -> 1.1319502 | K13: =$S$3 -> 0.97322576 | L13: =K13 -> 0.97322576 | M13: =$C$12*MAX(I13-K13,0) -> 0.31744891 | N13: =M13+L13 -> 1.2906747
B14: Mean E | C14: =(-B9^2)/2 -> 0 | H14: =IF($B$8=0, EXP($C$13), _xlfn.LOGNORM.INV(RAND(), $C$13, $B$8)) -> 1.010305 | I14: =IF($B$9=0, EXP($C$14), _xlfn.LOGNORM.INV(RAND(), $C$14, $B$9))*H14 -> 1.010305 | K14: =$S$3 -> 0.97322576 | L14: =K14 -> 0.97322576 | M14: =$C$12*MAX(I14-K14,0) -> 0.074158431 | N14: =M14+L14 -> 1.0473842
H15: =IF($B$8=0, EXP($C$13), _xlfn.LOGNORM.INV(RAND(), $C$13, $B$8)) -> 1.3091233 | I15: =IF($B$9=0, EXP($C$14), _xlfn.LOGNORM.INV(RAND(), $C$14, $B$9))*H15 -> 1.3091233 | K15: =$S$3 -> 0.97322576 | L15: =K15 -> 0.97322576 | M15: =$C$12*MAX(I15-K15,0) -> 0.6717951 | N15: =M15+L15 -> 1.6450209
H16: =IF($B$8=0, EXP($C$13), _xlfn.LOGNORM.INV(RAND(), $C$13, $B$8)) -> 1.0566238 | I16: =IF($B$9=0, EXP($C$14), _xlfn.LOGNORM.INV(RAND(), $C$14, $B$9))*H16 -> 1.0566238 | K16: =$S$3 -> 0.97322576 | L16: =K16 -> 0.97322576 | M16: =$C$12*MAX(I16-K16,0) -> 0.16679609 | N16: =M16+L16 -> 1.1400219
H17: =IF($B$8=0, EXP($C$13), _xlfn.LOGNORM.INV(RAND(), $C$13, $B$8)) -> 0.8725397 | I17: =IF($B$9=0, EXP($C$14), _xlfn.LOGNORM.INV(RAND(), $C$14, $B$9))*H17 -> 0.8725397 | K17: =$S$3 -> 0.97322576 | L17: =K17 -> 0.97322576 | M17: =$C$12*MAX(I17-K17,0) -> 0 | N17: =M17+L17 -> 0.97322576
H18: =IF($B$8=0, EXP($C$13), _xlfn.LOGNORM.INV(RAND(), $C$13, $B$8)) -> 0.74499256 | I18: =IF($B$9=0, EXP($C$14), _xlfn.LOGNORM.INV(RAND(), $C$14, $B$9))*H18 -> 0.74499256 | K18: =$S$3 -> 0.97322576 | L18: =K18 -> 0.97322576 | M18: =$C$12*MAX(I18-K18,0) -> 0 | N18: =M18+L18 -> 0.97322576
H19: =IF($B$8=0, EXP($C$13), _xlfn.LOGNORM.INV(RAND(), $C$13, $B$8)) -> 1.0629529 | I19: =IF($B$9=0, EXP($C$14), _xlfn.LOGNORM.INV(RAND(), $C$14, $B$9))*H19 -> 1.0629529 | K19: =$S$3 -> 0.97322576 | L19: =K19 -> 0.97322576 | M19: =$C$12*MAX(I19-K19,0) -> 0.17945431 | N19: =M19+L19 -> 1.1526801
H20: =IF($B$8=0, EXP($C$13), _xlfn.LOGNORM.INV(RAND(), $C$13, $B$8)) -> 0.66646153 | I20: =IF($B$9=0, EXP($C$14), _xlfn.LOGNORM.INV(RAND(), $C$14, $B$9))*H20 -> 0.66646153 | K20: =$S$3 -> 0.97322576 | L20: =K20 -> 0.97322576 | M20: =$C$12*MAX(I20-K20,0) -> 0 | N20: =M20+L20 -> 0.97322576
H21: =IF($B$8=0, EXP($C$13), _xlfn.LOGNORM.INV(RAND(), $C$13, $B$8)) -> 1.0508347 | I21: =IF($B$9=0, EXP($C$14), _xlfn.LOGNORM.INV(RAND(), $C$14, $B$9))*H21 -> 1.0508347 | K21: =$S$3 -> 0.97322576 | L21: =K21 -> 0.97322576 | M21: =$C$12*MAX(I21-K21,0) -> 0.15521784 | N21: =M21+L21 -> 1.1284436
H22: =IF($B$8=0, EXP($C$13), _xlfn.LOGNORM.INV(RAND(), $C$13, $B$8)) -> 0.93008888 | I22: =IF($B$9=0, EXP($C$14), _xlfn.LOGNORM.INV(RAND(), $C$14, $B$9))*H22 -> 0.93008888 | K22: =$S$3 -> 0.97322576 | L22: =K22 -> 0.97322576 | M22: =$C$12*MAX(I22-K22,0) -> 0 | N22: =M22+L22 -> 0.97322576
H23: =IF($B$8=0, EXP($C$13), _xlfn.LOGNORM.INV(RAND(), $C$13, $B$8)) -> 0.9547707 | I23: =IF($B$9=0, EXP($C$14), _xlfn.LOGNORM.INV(RAND(), $C$14, $B$9))*H23 -> 0.9547707 | K23: =$S$3 -> 0.97322576 | L23: =K23 -> 0.97322576 | M23: =$C$12*MAX(I23-K23,0) -> 0 | N23: =M23+L23 -> 0.97322576
H24: =IF($B$8=0, EXP($C$13), _xlfn.LOGNORM.INV(RAND(), $C$13, $B$8)) -> 1.1963136 | I24: =IF($B$9=0, EXP($C$14), _xlfn.LOGNORM.INV(RAND(), $C$14, $B$9))*H24 -> 1.1963136 | K24: =$S$3 -> 0.97322576 | L24: =K24 -> 0.97322576 | M24: =$C$12*MAX(I24-K24,0) -> 0.44617574 | N24: =M24+L24 -> 1.4194015
H25: =IF($B$8=0, EXP($C$13), _xlfn.LOGNORM.INV(RAND(), $C$13, $B$8)) -> 1.4134316 | I25: =IF($B$9=0, EXP($C$14), _xlfn.LOGNORM.INV(RAND(), $C$14, $B$9))*H25 -> 1.4134316 | K25: =$S$3 -> 0.97322576 | L25: =K25 -> 0.97322576 | M25: =$C$12*MAX(I25-K25,0) -> 0.88041173 | N25: =M25+L25 -> 1.8536375
H26: =IF($B$8=0, EXP($C$13), _xlfn.LOGNORM.INV(RAND(), $C$13, $B$8)) -> 1.6800482 | I26: =IF($B$9=0, EXP($C$14), _xlfn.LOGNORM.INV(RAND(), $C$14, $B$9))*H26 -> 1.6800482 | K26: =$S$3 -> 0.97322576 | L26: =K26 -> 0.97322576 | M26: =$C$12*MAX(I26-K26,0) -> 1.413645 | N26: =M26+L26 -> 2.3868707
... H1000: =IF($B$8=0, EXP($C$13), _xlfn.LOGNORM.INV(RAND(), $C$13, $B$8)) -> 1.0702702 | I1000: =IF($B$9=0, EXP($C$14), _xlfn.LOGNORM.INV(RAND(), $C$14, $B$9))*H1000 -> 1.0702702 | K1000: =$S$3 -> 0.97322576 | L1000: =K1000 -> 0.97322576 | M1000: =$C$12*MAX(I1000-K1000,0) -> 0.19408886 | N1000: =M1000+L1000 -> 1.1673146

Sheet MeNo
B2: Parameters | H2: D | I2: E | K2: S | L2: Cinv | M2: Cesf | N2: Ctot | P2: E[Cinv] | Q2: E[Cesf] | R2: E[Ctot] | S2: S
H3: =IF($B$8=0, EXP($C$13), _xlfn.LOGNORM.INV(RAND(), $C$13, $B$8)) -> 1.3336605 | I3: =IF($B$9=0, EXP($C$14), _xlfn.LOGNORM.INV(RAND(), $C$14, $B$9))*H3 -> 1.3336605 | K3: =$S$3 -> 1.1583175 | L3: =K3 -> 1.1583175 | M3: =$C$12*MAX(I3-K3,0) -> 0.35068615 | N3: =M3+L3 -> 1.5090036 | P3: =AVERAGE(L3:L1000) -> 1.1583175 | Q3: =AVERAGE(M3:M1000) -> 0.62510252 | R3: =AVERAGE(N3:N1000) -> 1.78342 | S3: 1.1583175
B4: Uncertainty(standard deviation) | C4: No | D4: Low | E4: Med | F4: High | H4: =IF($B$8=0, EXP($C$13), _xlfn.LOGNORM.INV(RAND(), $C$13, $B$8)) -> 0.8063715 | I4: =IF($B$9=0, EXP($C$14), _xlfn.LOGNORM.INV(RAND(), $C$14, $B$9))*H4 -> 0.8063715 | K4: =$S$3 -> 1.1583175 | L4: =K4 -> 1.1583175 | M4: =$C$12*MAX(I4-K4,0) -> 0 | N4: =M4+L4 -> 1.1583175
C5: 0 | D5: 0.25 | E5: 0.5 | F5: 0.75 | H5: =IF($B$8=0, EXP($C$13), _xlfn.LOGNORM.INV(RAND(), $C$13, $B$8)) -> 2.1620425 | I5: =IF($B$9=0, EXP($C$14), _xlfn.LOGNORM.INV(RAND(), $C$14, $B$9))*H5 -> 2.1620425 | K5: =$S$3 -> 1.1583175 | L5: =K5 -> 1.1583175 | M5: =$C$12*MAX(I5-K5,0) -> 2.00745 | N5: =M5+L5 -> 3.1657675
C6: 0 | D6: 0.25 | E6: 0.5 | F6: 0.75 | H6: =IF($B$8=0, EXP($C$13), _xlfn.LOGNORM.INV(RAND(), $C$13, $B$8)) -> 1.3870142 | I6: =IF($B$9=0, EXP($C$14), _xlfn.LOGNORM.INV(RAND(), $C$14, $B$9))*H6 -> 1.3870142 | K6: =$S$3 -> 1.1583175 | L6: =K6 -> 1.1583175 | M6: =$C$12*MAX(I6-K6,0) -> 0.45739346 | N6: =M6+L6 -> 1.6157109
H7: =IF($B$8=0, EXP($C$13), _xlfn.LOGNORM.INV(RAND(), $C$13, $B$8)) -> 1.2620284 | I7: =IF($B$9=0, EXP($C$14), _xlfn.LOGNORM.INV(RAND(), $C$14, $B$9))*H7 -> 1.2620284 | K7: =$S$3 -> 1.1583175 | L7: =K7 -> 1.1583175 | M7: =$C$12*MAX(I7-K7,0) -> 0.20742194 | N7: =M7+L7 -> 1.3657394
B8: =E5 -> 0.5 | C8: Current D uncertianty | H8: =IF($B$8=0, EXP($C$13), _xlfn.LOGNORM.INV(RAND(), $C$13, $B$8)) -> 1.0276727 | I8: =IF($B$9=0, EXP($C$14), _xlfn.LOGNORM.INV(RAND(), $C$14, $B$9))*H8 -> 1.0276727 | K8: =$S$3 -> 1.1583175 | L8: =K8 -> 1.1583175 | M8: =$C$12*MAX(I8-K8,0) -> 0 | N8: =M8+L8 -> 1.1583175
B9: =C6 -> 0 | C9: Current E uncertainty | H9: =IF($B$8=0, EXP($C$13), _xlfn.LOGNORM.INV(RAND(), $C$13, $B$8)) -> 2.1054888 | I9: =IF($B$9=0, EXP($C$14), _xlfn.LOGNORM.INV(RAND(), $C$14, $B$9))*H9 -> 2.1054888 | K9: =$S$3 -> 1.1583175 | L9: =K9 -> 1.1583175 | M9: =$C$12*MAX(I9-K9,0) -> 1.8943426 | N9: =M9+L9 -> 3.05266
H10: =IF($B$8=0, EXP($C$13), _xlfn.LOGNORM.INV(RAND(), $C$13, $B$8)) -> 2.4349698 | I10: =IF($B$9=0, EXP($C$14), _xlfn.LOGNORM.INV(RAND(), $C$14, $B$9))*H10 -> 2.4349698 | K10: =$S$3 -> 1.1583175 | L10: =K10 -> 1.1583175 | M10: =$C$12*MAX(I10-K10,0) -> 2.5533046 | N10: =M10+L10 -> 3.7116221
B11: Other parameters | H11: =IF($B$8=0, EXP($C$13), _xlfn.LOGNORM.INV(RAND(), $C$13, $B$8)) -> 1.4274768 | I11: =IF($B$9=0, EXP($C$14), _xlfn.LOGNORM.INV(RAND(), $C$14, $B$9))*H11 -> 1.4274768 | K11: =$S$3 -> 1.1583175 | L11: =K11 -> 1.1583175 | M11: =$C$12*MAX(I11-K11,0) -> 0.53831866 | N11: =M11+L11 -> 1.6966361
B12: c^s | C12: =Model!C12 -> 2 | H12: =IF($B$8=0, EXP($C$13), _xlfn.LOGNORM.INV(RAND(), $C$13, $B$8)) -> 1.0938252 | I12: =IF($B$9=0, EXP($C$14), _xlfn.LOGNORM.INV(RAND(), $C$14, $B$9))*H12 -> 1.0938252 | K12: =$S$3 -> 1.1583175 | L12: =K12 -> 1.1583175 | M12: =$C$12*MAX(I12-K12,0) -> 0 | N12: =M12+L12 -> 1.1583175
B13: Mean D | C13: =(-B8^2)/2 -> 0.125 | H13: =IF($B$8=0, EXP($C$13), _xlfn.LOGNORM.INV(RAND(), $C$13, $B$8)) -> 1.3818492 | I13: =IF($B$9=0, EXP($C$14), _xlfn.LOGNORM.INV(RAND(), $C$14, $B$9))*H13 -> 1.3818492 | K13: =$S$3 -> 1.1583175 | L13: =K13 -> 1.1583175 | M13: =$C$12*MAX(I13-K13,0) -> 0.44706347 | N13: =M13+L13 -> 1.6053809
B14: Mean E | C14: =(-B9^2)/2 -> 0 | H14: =IF($B$8=0, EXP($C$13), _xlfn.LOGNORM.INV(RAND(), $C$13, $B$8)) -> 0.94559562 | I14: =IF($B$9=0, EXP($C$14), _xlfn.LOGNORM.INV(RAND(), $C$14, $B$9))*H14 -> 0.94559562 | K14: =$S$3 -> 1.1583175 | L14: =K14 -> 1.1583175 | M14: =$C$12*MAX(I14-K14,0) -> 0 | N14: =M14+L14 -> 1.1583175
H15: =IF($B$8=0, EXP($C$13), _xlfn.LOGNORM.INV(RAND(), $C$13, $B$8)) -> 1.079657 | I15: =IF($B$9=0, EXP($C$14), _xlfn.LOGNORM.INV(RAND(), $C$14, $B$9))*H15 -> 1.079657 | K15: =$S$3 -> 1.1583175 | L15: =K15 -> 1.1583175 | M15: =$C$12*MAX(I15-K15,0) -> 0 | N15: =M15+L15 -> 1.1583175
H16: =IF($B$8=0, EXP($C$13), _xlfn.LOGNORM.INV(RAND(), $C$13, $B$8)) -> 1.1951923 | I16: =IF($B$9=0, EXP($C$14), _xlfn.LOGNORM.INV(RAND(), $C$14, $B$9))*H16 -> 1.1951923 | K16: =$S$3 -> 1.1583175 | L16: =K16 -> 1.1583175 | M16: =$C$12*MAX(I16-K16,0) -> 0.073749574 | N16: =M16+L16 -> 1.232067
H17: =IF($B$8=0, EXP($C$13), _xlfn.LOGNORM.INV(RAND(), $C$13, $B$8)) -> 1.9038001 | I17: =IF($B$9=0, EXP($C$14), _xlfn.LOGNORM.INV(RAND(), $C$14, $B$9))*H17 -> 1.9038001 | K17: =$S$3 -> 1.1583175 | L17: =K17 -> 1.1583175 | M17: =$C$12*MAX(I17-K17,0) -> 1.4909653 | N17: =M17+L17 -> 2.6492827
H18: =IF($B$8=0, EXP($C$13), _xlfn.LOGNORM.INV(RAND(), $C$13, $B$8)) -> 0.69750473 | I18: =IF($B$9=0, EXP($C$14), _xlfn.LOGNORM.INV(RAND(), $C$14, $B$9))*H18 -> 0.69750473 | K18: =$S$3 -> 1.1583175 | L18: =K18 -> 1.1583175 | M18: =$C$12*MAX(I18-K18,0) -> 0 | N18: =M18+L18 -> 1.1583175
H19: =IF($B$8=0, EXP($C$13), _xlfn.LOGNORM.INV(RAND(), $C$13, $B$8)) -> 0.54126269 | I19: =IF($B$9=0, EXP($C$14), _xlfn.LOGNORM.INV(RAND(), $C$14, $B$9))*H19 -> 0.54126269 | K19: =$S$3 -> 1.1583175 | L19: =K19 -> 1.1583175 | M19: =$C$12*MAX(I19-K19,0) -> 0 | N19: =M19+L19 -> 1.1583175
H20: =IF($B$8=0, EXP($C$13), _xlfn.LOGNORM.INV(RAND(), $C$13, $B$8)) -> 1.6347096 | I20: =IF($B$9=0, EXP($C$14), _xlfn.LOGNORM.INV(RAND(), $C$14, $B$9))*H20 -> 1.6347096 | K20: =$S$3 -> 1.1583175 | L20: =K20 -> 1.1583175 | M20: =$C$12*MAX(I20-K20,0) -> 0.95278433 | N20: =M20+L20 -> 2.1111018
H21: =IF($B$8=0, EXP($C$13), _xlfn.LOGNORM.INV(RAND(), $C$13, $B$8)) -> 2.2122191 | I21: =IF($B$9=0, EXP($C$14), _xlfn.LOGNORM.INV(RAND(), $C$14, $B$9))*H21 -> 2.2122191 | K21: =$S$3 -> 1.1583175 | L21: =K21 -> 1.1583175 | M21: =$C$12*MAX(I21-K21,0) -> 2.1078032 | N21: =M21+L21 -> 3.2661207
H22: =IF($B$8=0, EXP($C$13), _xlfn.LOGNORM.INV(RAND(), $C$13, $B$8)) -> 2.1439644 | I22: =IF($B$9=0, EXP($C$14), _xlfn.LOGNORM.INV(RAND(), $C$14, $B$9))*H22 -> 2.1439644 | K22: =$S$3 -> 1.1583175 | L22: =K22 -> 1.1583175 | M22: =$C$12*MAX(I22-K22,0) -> 1.9712938 | N22: =M22+L22 -> 3.1296112
H23: =IF($B$8=0, EXP($C$13), _xlfn.LOGNORM.INV(RAND(), $C$13, $B$8)) -> 0.67705533 | I23: =IF($B$9=0, EXP($C$14), _xlfn.LOGNORM.INV(RAND(), $C$14, $B$9))*H23 -> 0.67705533 | K23: =$S$3 -> 1.1583175 | L23: =K23 -> 1.1583175 | M23: =$C$12*MAX(I23-K23,0) -> 0 | N23: =M23+L23 -> 1.1583175
H24: =IF($B$8=0, EXP($C$13), _xlfn.LOGNORM.INV(RAND(), $C$13, $B$8)) -> 1.3368201 | I24: =IF($B$9=0, EXP($C$14), _xlfn.LOGNORM.INV(RAND(), $C$14, $B$9))*H24 -> 1.3368201 | K24: =$S$3 -> 1.1583175 | L24: =K24 -> 1.1583175 | M24: =$C$12*MAX(I24-K24,0) -> 0.35700535 | N24: =M24+L24 -> 1.5153228
H25: =IF($B$8=0, EXP($C$13), _xlfn.LOGNORM.INV(RAND(), $C$13, $B$8)) -> 0.84399535 | I25: =IF($B$9=0, EXP($C$14), _xlfn.LOGNORM.INV(RAND(), $C$14, $B$9))*H25 -> 0.84399535 | K25: =$S$3 -> 1.1583175 | L25: =K25 -> 1.1583175 | M25: =$C$12*MAX(I25-K25,0) -> 0 | N25: =M25+L25 -> 1.1583175
H26: =IF($B$8=0, EXP($C$13), _xlfn.LOGNORM.INV(RAND(), $C$13, $B$8)) -> 1.0626933 | I26: =IF($B$9=0, EXP($C$14), _xlfn.LOGNORM.INV(RAND(), $C$14, $B$9))*H26 -> 1.0626933 | K26: =$S$3 -> 1.1583175 | L26: =K26 -> 1.1583175 | M26: =$C$12*MAX(I26-K26,0) -> 0 | N26: =M26+L26 -> 1.1583175
... H1000: =IF($B$8=0, EXP($C$13), _xlfn.LOGNORM.INV(RAND(), $C$13, $B$8)) -> 2.8384472 | I1000: =IF($B$9=0, EXP($C$14), _xlfn.LOGNORM.INV(RAND(), $C$14, $B$9))*H1000 -> 2.8384472 | K1000: =$S$3 -> 1.1583175 | L1000: =K1000 -> 1.1583175 | M1000: =$C$12*MAX(I1000-K1000,0) -> 3.3602595 | N1000: =M1000+L1000 -> 4.5185769

Sheet HiNo
B2: Parameters | H2: D | I2: E | K2: S | L2: Cinv | M2: Cesf | N2: Ctot | P2: E[Cinv] | Q2: E[Cesf] | R2: E[Ctot] | S2: S
H3: =IF($B$8=0, EXP($C$13), _xlfn.LOGNORM.INV(RAND(), $C$13, $B$8)) -> 0.4059131 | I3: =IF($B$9=0, EXP($C$14), _xlfn.LOGNORM.INV(RAND(), $C$14, $B$9))*H3 -> 0.4059131 | K3: =$S$3 -> 2.4017505 | L3: =K3 -> 2.4017505 | M3: =$C$12*MAX(I3-K3,0) -> 0 | N3: =M3+L3 -> 2.4017505 | P3: =AVERAGE(L3:L1000) -> 2.4017505 | Q3: =AVERAGE(M3:M1000) -> 0.65194918 | R3: =AVERAGE(N3:N1000) -> 3.0536997 | S3: 2.4017505
B4: Uncertainty(standard deviation) | C4: No | D4: Low | E4: Med | F4: High | H4: =IF($B$8=0, EXP($C$13), _xlfn.LOGNORM.INV(RAND(), $C$13, $B$8)) -> 0.86621714 | I4: =IF($B$9=0, EXP($C$14), _xlfn.LOGNORM.INV(RAND(), $C$14, $B$9))*H4 -> 0.86621714 | K4: =$S$3 -> 2.4017505 | L4: =K4 -> 2.4017505 | M4: =$C$12*MAX(I4-K4,0) -> 0 | N4: =M4+L4 -> 2.4017505
C5: 0 | D5: 0.25 | E5: 0.5 | F5: 0.75 | H5: =IF($B$8=0, EXP($C$13), _xlfn.LOGNORM.INV(RAND(), $C$13, $B$8)) -> 0.41441676 | I5: =IF($B$9=0, EXP($C$14), _xlfn.LOGNORM.INV(RAND(), $C$14, $B$9))*H5 -> 0.41441676 | K5: =$S$3 -> 2.4017505 | L5: =K5 -> 2.4017505 | M5: =$C$12*MAX(I5-K5,0) -> 0 | N5: =M5+L5 -> 2.4017505
C6: 0 | D6: 0.25 | E6: 0.5 | F6: 0.75 | H6: =IF($B$8=0, EXP($C$13), _xlfn.LOGNORM.INV(RAND(), $C$13, $B$8)) -> 0.27889115 | I6: =IF($B$9=0, EXP($C$14), _xlfn.LOGNORM.INV(RAND(), $C$14, $B$9))*H6 -> 0.27889115 | K6: =$S$3 -> 2.4017505 | L6: =K6 -> 2.4017505 | M6: =$C$12*MAX(I6-K6,0) -> 0 | N6: =M6+L6 -> 2.4017505
H7: =IF($B$8=0, EXP($C$13), _xlfn.LOGNORM.INV(RAND(), $C$13, $B$8)) -> 1.5370852 | I7: =IF($B$9=0, EXP($C$14), _xlfn.LOGNORM.INV(RAND(), $C$14, $B$9))*H7 -> 1.5370852 | K7: =$S$3 -> 2.4017505 | L7: =K7 -> 2.4017505 | M7: =$C$12*MAX(I7-K7,0) -> 0 | N7: =M7+L7 -> 2.4017505
B8: =F5 -> 0.75 | C8: Current D uncertianty | H8: =IF($B$8=0, EXP($C$13), _xlfn.LOGNORM.INV(RAND(), $C$13, $B$8)) -> 1.8210912 | I8: =IF($B$9=0, EXP($C$14), _xlfn.LOGNORM.INV(RAND(), $C$14, $B$9))*H8 -> 1.8210912 | K8: =$S$3 -> 2.4017505 | L8: =K8 -> 2.4017505 | M8: =$C$12*MAX(I8-K8,0) -> 0 | N8: =M8+L8 -> 2.4017505
B9: =C6 -> 0 | C9: Current E uncertainty | H9: =IF($B$8=0, EXP($C$13), _xlfn.LOGNORM.INV(RAND(), $C$13, $B$8)) -> 1.1219997 | I9: =IF($B$9=0, EXP($C$14), _xlfn.LOGNORM.INV(RAND(), $C$14, $B$9))*H9 -> 1.1219997 | K9: =$S$3 -> 2.4017505 | L9: =K9 -> 2.4017505 | M9: =$C$12*MAX(I9-K9,0) -> 0 | N9: =M9+L9 -> 2.4017505
H10: =IF($B$8=0, EXP($C$13), _xlfn.LOGNORM.INV(RAND(), $C$13, $B$8)) -> 1.1305958 | I10: =IF($B$9=0, EXP($C$14), _xlfn.LOGNORM.INV(RAND(), $C$14, $B$9))*H10 -> 1.1305958 | K10: =$S$3 -> 2.4017505 | L10: =K10 -> 2.4017505 | M10: =$C$12*MAX(I10-K10,0) -> 0 | N10: =M10+L10 -> 2.4017505
B11: Other parameters | H11: =IF($B$8=0, EXP($C$13), _xlfn.LOGNORM.INV(RAND(), $C$13, $B$8)) -> 1.6087531 | I11: =IF($B$9=0, EXP($C$14), _xlfn.LOGNORM.INV(RAND(), $C$14, $B$9))*H11 -> 1.6087531 | K11: =$S$3 -> 2.4017505 | L11: =K11 -> 2.4017505 | M11: =$C$12*MAX(I11-K11,0) -> 0 | N11: =M11+L11 -> 2.4017505
B12: c^s | C12: =Model!C12 -> 2 | H12: =IF($B$8=0, EXP($C$13), _xlfn.LOGNORM.INV(RAND(), $C$13, $B$8)) -> 2.1491407 | I12: =IF($B$9=0, EXP($C$14), _xlfn.LOGNORM.INV(RAND(), $C$14, $B$9))*H12 -> 2.1491407 | K12: =$S$3 -> 2.4017505 | L12: =K12 -> 2.4017505 | M12: =$C$12*MAX(I12-K12,0) -> 0 | N12: =M12+L12 -> 2.4017505
B13: Mean D | C13: =(-B8^2)/2 -> 0.28125 | H13: =IF($B$8=0, EXP($C$13), _xlfn.LOGNORM.INV(RAND(), $C$13, $B$8)) -> 2.624728 | I13: =IF($B$9=0, EXP($C$14), _xlfn.LOGNORM.INV(RAND(), $C$14, $B$9))*H13 -> 2.624728 | K13: =$S$3 -> 2.4017505 | L13: =K13 -> 2.4017505 | M13: =$C$12*MAX(I13-K13,0) -> 0.44595501 | N13: =M13+L13 -> 2.8477055
B14: Mean E | C14: =(-B9^2)/2 -> 0 | H14: =IF($B$8=0, EXP($C$13), _xlfn.LOGNORM.INV(RAND(), $C$13, $B$8)) -> 2.0806804 | I14: =IF($B$9=0, EXP($C$14), _xlfn.LOGNORM.INV(RAND(), $C$14, $B$9))*H14 -> 2.0806804 | K14: =$S$3 -> 2.4017505 | L14: =K14 -> 2.4017505 | M14: =$C$12*MAX(I14-K14,0) -> 0 | N14: =M14+L14 -> 2.4017505
H15: =IF($B$8=0, EXP($C$13), _xlfn.LOGNORM.INV(RAND(), $C$13, $B$8)) -> 7.3071472 | I15: =IF($B$9=0, EXP($C$14), _xlfn.LOGNORM.INV(RAND(), $C$14, $B$9))*H15 -> 7.3071472 | K15: =$S$3 -> 2.4017505 | L15: =K15 -> 2.4017505 | M15: =$C$12*MAX(I15-K15,0) -> 9.8107933 | N15: =M15+L15 -> 12.212544
H16: =IF($B$8=0, EXP($C$13), _xlfn.LOGNORM.INV(RAND(), $C$13, $B$8)) -> 5.3924227 | I16: =IF($B$9=0, EXP($C$14), _xlfn.LOGNORM.INV(RAND(), $C$14, $B$9))*H16 -> 5.3924227 | K16: =$S$3 -> 2.4017505 | L16: =K16 -> 2.4017505 | M16: =$C$12*MAX(I16-K16,0) -> 5.9813443 | N16: =M16+L16 -> 8.3830948
H17: =IF($B$8=0, EXP($C$13), _xlfn.LOGNORM.INV(RAND(), $C$13, $B$8)) -> 4.1231372 | I17: =IF($B$9=0, EXP($C$14), _xlfn.LOGNORM.INV(RAND(), $C$14, $B$9))*H17 -> 4.1231372 | K17: =$S$3 -> 2.4017505 | L17: =K17 -> 2.4017505 | M17: =$C$12*MAX(I17-K17,0) -> 3.4427733 | N17: =M17+L17 -> 5.8445238
H18: =IF($B$8=0, EXP($C$13), _xlfn.LOGNORM.INV(RAND(), $C$13, $B$8)) -> 1.9613788 | I18: =IF($B$9=0, EXP($C$14), _xlfn.LOGNORM.INV(RAND(), $C$14, $B$9))*H18 -> 1.9613788 | K18: =$S$3 -> 2.4017505 | L18: =K18 -> 2.4017505 | M18: =$C$12*MAX(I18-K18,0) -> 0 | N18: =M18+L18 -> 2.4017505
H19: =IF($B$8=0, EXP($C$13), _xlfn.LOGNORM.INV(RAND(), $C$13, $B$8)) -> 0.81157015 | I19: =IF($B$9=0, EXP($C$14), _xlfn.LOGNORM.INV(RAND(), $C$14, $B$9))*H19 -> 0.81157015 | K19: =$S$3 -> 2.4017505 | L19: =K19 -> 2.4017505 | M19: =$C$12*MAX(I19-K19,0) -> 0 | N19: =M19+L19 -> 2.4017505
H20: =IF($B$8=0, EXP($C$13), _xlfn.LOGNORM.INV(RAND(), $C$13, $B$8)) -> 0.76368813 | I20: =IF($B$9=0, EXP($C$14), _xlfn.LOGNORM.INV(RAND(), $C$14, $B$9))*H20 -> 0.76368813 | K20: =$S$3 -> 2.4017505 | L20: =K20 -> 2.4017505 | M20: =$C$12*MAX(I20-K20,0) -> 0 | N20: =M20+L20 -> 2.4017505
H21: =IF($B$8=0, EXP($C$13), _xlfn.LOGNORM.INV(RAND(), $C$13, $B$8)) -> 0.71567347 | I21: =IF($B$9=0, EXP($C$14), _xlfn.LOGNORM.INV(RAND(), $C$14, $B$9))*H21 -> 0.71567347 | K21: =$S$3 -> 2.4017505 | L21: =K21 -> 2.4017505 | M21: =$C$12*MAX(I21-K21,0) -> 0 | N21: =M21+L21 -> 2.4017505
H22: =IF($B$8=0, EXP($C$13), _xlfn.LOGNORM.INV(RAND(), $C$13, $B$8)) -> 5.8597699 | I22: =IF($B$9=0, EXP($C$14), _xlfn.LOGNORM.INV(RAND(), $C$14, $B$9))*H22 -> 5.8597699 | K22: =$S$3 -> 2.4017505 | L22: =K22 -> 2.4017505 | M22: =$C$12*MAX(I22-K22,0) -> 6.9160388 | N22: =M22+L22 -> 9.3177893
H23: =IF($B$8=0, EXP($C$13), _xlfn.LOGNORM.INV(RAND(), $C$13, $B$8)) -> 1.464411 | I23: =IF($B$9=0, EXP($C$14), _xlfn.LOGNORM.INV(RAND(), $C$14, $B$9))*H23 -> 1.464411 | K23: =$S$3 -> 2.4017505 | L23: =K23 -> 2.4017505 | M23: =$C$12*MAX(I23-K23,0) -> 0 | N23: =M23+L23 -> 2.4017505
H24: =IF($B$8=0, EXP($C$13), _xlfn.LOGNORM.INV(RAND(), $C$13, $B$8)) -> 5.2595668 | I24: =IF($B$9=0, EXP($C$14), _xlfn.LOGNORM.INV(RAND(), $C$14, $B$9))*H24 -> 5.2595668 | K24: =$S$3 -> 2.4017505 | L24: =K24 -> 2.4017505 | M24: =$C$12*MAX(I24-K24,0) -> 5.7156326 | N24: =M24+L24 -> 8.1173831
H25: =IF($B$8=0, EXP($C$13), _xlfn.LOGNORM.INV(RAND(), $C$13, $B$8)) -> 3.8800629 | I25: =IF($B$9=0, EXP($C$14), _xlfn.LOGNORM.INV(RAND(), $C$14, $B$9))*H25 -> 3.8800629 | K25: =$S$3 -> 2.4017505 | L25: =K25 -> 2.4017505 | M25: =$C$12*MAX(I25-K25,0) -> 2.9566247 | N25: =M25+L25 -> 5.3583752
H26: =IF($B$8=0, EXP($C$13), _xlfn.LOGNORM.INV(RAND(), $C$13, $B$8)) -> 1.136229 | I26: =IF($B$9=0, EXP($C$14), _xlfn.LOGNORM.INV(RAND(), $C$14, $B$9))*H26 -> 1.136229 | K26: =$S$3 -> 2.4017505 | L26: =K26 -> 2.4017505 | M26: =$C$12*MAX(I26-K26,0) -> 0 | N26: =M26+L26 -> 2.4017505
... H1000: =IF($B$8=0, EXP($C$13), _xlfn.LOGNORM.INV(RAND(), $C$13, $B$8)) -> 2.801568 | I1000: =IF($B$9=0, EXP($C$14), _xlfn.LOGNORM.INV(RAND(), $C$14, $B$9))*H1000 -> 2.801568 | K1000: =$S$3 -> 2.4017505 | L1000: =K1000 -> 2.4017505 | M1000: =$C$12*MAX(I1000-K1000,0) -> 0.79963495 | N1000: =M1000+L1000 -> 3.2013855

Sheet NoLo
B2: Parameters | H2: D | I2: E | K2: S | L2: Cinv | M2: Cesf | N2: Ctot | P2: E[Cinv] | Q2: E[Cesf] | R2: E[Ctot] | S2: S
H3: =IF($B$8=0, EXP($C$13), _xlfn.LOGNORM.INV(RAND(), $C$13, $B$8)) -> 1 | I3: =IF($B$9=0, EXP($C$14), _xlfn.LOGNORM.INV(RAND(), $C$14, $B$9))*H3 -> 0.9291488 | K3: =$S$3 -> 1.3633031 | L3: =K3 -> 1.3633031 | M3: =$C$12*MAX(I3-K3,0) -> 0 | N3: =M3+L3 -> 1.3633031 | P3: =AVERAGE(L3:L1000) -> 1.3633031 | Q3: =AVERAGE(M3:M1000) -> 0.050987897 | R3: =AVERAGE(N3:N1000) -> 1.414291 | S3: 1.3633031
B4: Uncertainty(standard deviation) | C4: No | D4: Low | E4: Med | F4: High | H4: =IF($B$8=0, EXP($C$13), _xlfn.LOGNORM.INV(RAND(), $C$13, $B$8)) -> 1 | I4: =IF($B$9=0, EXP($C$14), _xlfn.LOGNORM.INV(RAND(), $C$14, $B$9))*H4 -> 0.81535717 | K4: =$S$3 -> 1.3633031 | L4: =K4 -> 1.3633031 | M4: =$C$12*MAX(I4-K4,0) -> 0 | N4: =M4+L4 -> 1.3633031
C5: 0 | D5: 0.25 | E5: 0.5 | F5: 0.75 | H5: =IF($B$8=0, EXP($C$13), _xlfn.LOGNORM.INV(RAND(), $C$13, $B$8)) -> 1 | I5: =IF($B$9=0, EXP($C$14), _xlfn.LOGNORM.INV(RAND(), $C$14, $B$9))*H5 -> 1.2237628 | K5: =$S$3 -> 1.3633031 | L5: =K5 -> 1.3633031 | M5: =$C$12*MAX(I5-K5,0) -> 0 | N5: =M5+L5 -> 1.3633031
C6: 0 | D6: 0.25 | E6: 0.5 | F6: 0.75 | H6: =IF($B$8=0, EXP($C$13), _xlfn.LOGNORM.INV(RAND(), $C$13, $B$8)) -> 1 | I6: =IF($B$9=0, EXP($C$14), _xlfn.LOGNORM.INV(RAND(), $C$14, $B$9))*H6 -> 0.90577741 | K6: =$S$3 -> 1.3633031 | L6: =K6 -> 1.3633031 | M6: =$C$12*MAX(I6-K6,0) -> 0 | N6: =M6+L6 -> 1.3633031
H7: =IF($B$8=0, EXP($C$13), _xlfn.LOGNORM.INV(RAND(), $C$13, $B$8)) -> 1 | I7: =IF($B$9=0, EXP($C$14), _xlfn.LOGNORM.INV(RAND(), $C$14, $B$9))*H7 -> 1.0722844 | K7: =$S$3 -> 1.3633031 | L7: =K7 -> 1.3633031 | M7: =$C$12*MAX(I7-K7,0) -> 0 | N7: =M7+L7 -> 1.3633031
B8: =C5 -> 0 | C8: Current D uncertianty | H8: =IF($B$8=0, EXP($C$13), _xlfn.LOGNORM.INV(RAND(), $C$13, $B$8)) -> 1 | I8: =IF($B$9=0, EXP($C$14), _xlfn.LOGNORM.INV(RAND(), $C$14, $B$9))*H8 -> 1.291321 | K8: =$S$3 -> 1.3633031 | L8: =K8 -> 1.3633031 | M8: =$C$12*MAX(I8-K8,0) -> 0 | N8: =M8+L8 -> 1.3633031
B9: =D6 -> 0.25 | C9: Current E uncertainty | H9: =IF($B$8=0, EXP($C$13), _xlfn.LOGNORM.INV(RAND(), $C$13, $B$8)) -> 1 | I9: =IF($B$9=0, EXP($C$14), _xlfn.LOGNORM.INV(RAND(), $C$14, $B$9))*H9 -> 1.5675924 | K9: =$S$3 -> 1.3633031 | L9: =K9 -> 1.3633031 | M9: =$C$12*MAX(I9-K9,0) -> 0.40857856 | N9: =M9+L9 -> 1.7718817
H10: =IF($B$8=0, EXP($C$13), _xlfn.LOGNORM.INV(RAND(), $C$13, $B$8)) -> 1 | I10: =IF($B$9=0, EXP($C$14), _xlfn.LOGNORM.INV(RAND(), $C$14, $B$9))*H10 -> 0.91328549 | K10: =$S$3 -> 1.3633031 | L10: =K10 -> 1.3633031 | M10: =$C$12*MAX(I10-K10,0) -> 0 | N10: =M10+L10 -> 1.3633031
B11: Other parameters | H11: =IF($B$8=0, EXP($C$13), _xlfn.LOGNORM.INV(RAND(), $C$13, $B$8)) -> 1 | I11: =IF($B$9=0, EXP($C$14), _xlfn.LOGNORM.INV(RAND(), $C$14, $B$9))*H11 -> 0.75362379 | K11: =$S$3 -> 1.3633031 | L11: =K11 -> 1.3633031 | M11: =$C$12*MAX(I11-K11,0) -> 0 | N11: =M11+L11 -> 1.3633031
B12: c^s | C12: =Model!C12 -> 2 | H12: =IF($B$8=0, EXP($C$13), _xlfn.LOGNORM.INV(RAND(), $C$13, $B$8)) -> 1 | I12: =IF($B$9=0, EXP($C$14), _xlfn.LOGNORM.INV(RAND(), $C$14, $B$9))*H12 -> 0.89890099 | K12: =$S$3 -> 1.3633031 | L12: =K12 -> 1.3633031 | M12: =$C$12*MAX(I12-K12,0) -> 0 | N12: =M12+L12 -> 1.3633031
B13: Mean D | C13: =(-B8^2)/2 -> 0 | H13: =IF($B$8=0, EXP($C$13), _xlfn.LOGNORM.INV(RAND(), $C$13, $B$8)) -> 1 | I13: =IF($B$9=0, EXP($C$14), _xlfn.LOGNORM.INV(RAND(), $C$14, $B$9))*H13 -> 0.99082054 | K13: =$S$3 -> 1.3633031 | L13: =K13 -> 1.3633031 | M13: =$C$12*MAX(I13-K13,0) -> 0 | N13: =M13+L13 -> 1.3633031
B14: Mean E | C14: =(-B9^2)/2 -> 0.03125 | H14: =IF($B$8=0, EXP($C$13), _xlfn.LOGNORM.INV(RAND(), $C$13, $B$8)) -> 1 | I14: =IF($B$9=0, EXP($C$14), _xlfn.LOGNORM.INV(RAND(), $C$14, $B$9))*H14 -> 0.79102848 | K14: =$S$3 -> 1.3633031 | L14: =K14 -> 1.3633031 | M14: =$C$12*MAX(I14-K14,0) -> 0 | N14: =M14+L14 -> 1.3633031
H15: =IF($B$8=0, EXP($C$13), _xlfn.LOGNORM.INV(RAND(), $C$13, $B$8)) -> 1 | I15: =IF($B$9=0, EXP($C$14), _xlfn.LOGNORM.INV(RAND(), $C$14, $B$9))*H15 -> 0.72636424 | K15: =$S$3 -> 1.3633031 | L15: =K15 -> 1.3633031 | M15: =$C$12*MAX(I15-K15,0) -> 0 | N15: =M15+L15 -> 1.3633031
H16: =IF($B$8=0, EXP($C$13), _xlfn.LOGNORM.INV(RAND(), $C$13, $B$8)) -> 1 | I16: =IF($B$9=0, EXP($C$14), _xlfn.LOGNORM.INV(RAND(), $C$14, $B$9))*H16 -> 1.0966922 | K16: =$S$3 -> 1.3633031 | L16: =K16 -> 1.3633031 | M16: =$C$12*MAX(I16-K16,0) -> 0 | N16: =M16+L16 -> 1.3633031
H17: =IF($B$8=0, EXP($C$13), _xlfn.LOGNORM.INV(RAND(), $C$13, $B$8)) -> 1 | I17: =IF($B$9=0, EXP($C$14), _xlfn.LOGNORM.INV(RAND(), $C$14, $B$9))*H17 -> 1.06803 | K17: =$S$3 -> 1.3633031 | L17: =K17 -> 1.3633031 | M17: =$C$12*MAX(I17-K17,0) -> 0 | N17: =M17+L17 -> 1.3633031
H18: =IF($B$8=0, EXP($C$13), _xlfn.LOGNORM.INV(RAND(), $C$13, $B$8)) -> 1 | I18: =IF($B$9=0, EXP($C$14), _xlfn.LOGNORM.INV(RAND(), $C$14, $B$9))*H18 -> 0.64572095 | K18: =$S$3 -> 1.3633031 | L18: =K18 -> 1.3633031 | M18: =$C$12*MAX(I18-K18,0) -> 0 | N18: =M18+L18 -> 1.3633031
H19: =IF($B$8=0, EXP($C$13), _xlfn.LOGNORM.INV(RAND(), $C$13, $B$8)) -> 1 | I19: =IF($B$9=0, EXP($C$14), _xlfn.LOGNORM.INV(RAND(), $C$14, $B$9))*H19 -> 1.0024386 | K19: =$S$3 -> 1.3633031 | L19: =K19 -> 1.3633031 | M19: =$C$12*MAX(I19-K19,0) -> 0 | N19: =M19+L19 -> 1.3633031
H20: =IF($B$8=0, EXP($C$13), _xlfn.LOGNORM.INV(RAND(), $C$13, $B$8)) -> 1 | I20: =IF($B$9=0, EXP($C$14), _xlfn.LOGNORM.INV(RAND(), $C$14, $B$9))*H20 -> 1.2186032 | K20: =$S$3 -> 1.3633031 | L20: =K20 -> 1.3633031 | M20: =$C$12*MAX(I20-K20,0) -> 0 | N20: =M20+L20 -> 1.3633031
H21: =IF($B$8=0, EXP($C$13), _xlfn.LOGNORM.INV(RAND(), $C$13, $B$8)) -> 1 | I21: =IF($B$9=0, EXP($C$14), _xlfn.LOGNORM.INV(RAND(), $C$14, $B$9))*H21 -> 1.375656 | K21: =$S$3 -> 1.3633031 | L21: =K21 -> 1.3633031 | M21: =$C$12*MAX(I21-K21,0) -> 0.024705797 | N21: =M21+L21 -> 1.3880089
H22: =IF($B$8=0, EXP($C$13), _xlfn.LOGNORM.INV(RAND(), $C$13, $B$8)) -> 1 | I22: =IF($B$9=0, EXP($C$14), _xlfn.LOGNORM.INV(RAND(), $C$14, $B$9))*H22 -> 0.76932331 | K22: =$S$3 -> 1.3633031 | L22: =K22 -> 1.3633031 | M22: =$C$12*MAX(I22-K22,0) -> 0 | N22: =M22+L22 -> 1.3633031
H23: =IF($B$8=0, EXP($C$13), _xlfn.LOGNORM.INV(RAND(), $C$13, $B$8)) -> 1 | I23: =IF($B$9=0, EXP($C$14), _xlfn.LOGNORM.INV(RAND(), $C$14, $B$9))*H23 -> 1.3043736 | K23: =$S$3 -> 1.3633031 | L23: =K23 -> 1.3633031 | M23: =$C$12*MAX(I23-K23,0) -> 0 | N23: =M23+L23 -> 1.3633031
H24: =IF($B$8=0, EXP($C$13), _xlfn.LOGNORM.INV(RAND(), $C$13, $B$8)) -> 1 | I24: =IF($B$9=0, EXP($C$14), _xlfn.LOGNORM.INV(RAND(), $C$14, $B$9))*H24 -> 0.94082378 | K24: =$S$3 -> 1.3633031 | L24: =K24 -> 1.3633031 | M24: =$C$12*MAX(I24-K24,0) -> 0 | N24: =M24+L24 -> 1.3633031
H25: =IF($B$8=0, EXP($C$13), _xlfn.LOGNORM.INV(RAND(), $C$13, $B$8)) -> 1 | I25: =IF($B$9=0, EXP($C$14), _xlfn.LOGNORM.INV(RAND(), $C$14, $B$9))*H25 -> 1.0991475 | K25: =$S$3 -> 1.3633031 | L25: =K25 -> 1.3633031 | M25: =$C$12*MAX(I25-K25,0) -> 0 | N25: =M25+L25 -> 1.3633031
H26: =IF($B$8=0, EXP($C$13), _xlfn.LOGNORM.INV(RAND(), $C$13, $B$8)) -> 1 | I26: =IF($B$9=0, EXP($C$14), _xlfn.LOGNORM.INV(RAND(), $C$14, $B$9))*H26 -> 1.1416991 | K26: =$S$3 -> 1.3633031 | L26: =K26 -> 1.3633031 | M26: =$C$12*MAX(I26-K26,0) -> 0 | N26: =M26+L26 -> 1.3633031
... H1000: =IF($B$8=0, EXP($C$13), _xlfn.LOGNORM.INV(RAND(), $C$13, $B$8)) -> 1 | I1000: =IF($B$9=0, EXP($C$14), _xlfn.LOGNORM.INV(RAND(), $C$14, $B$9))*H1000 -> 1.3227266 | K1000: =$S$3 -> 1.3633031 | L1000: =K1000 -> 1.3633031 | M1000: =$C$12*MAX(I1000-K1000,0) -> 0 | N1000: =M1000+L1000 -> 1.3633031

Sheet LoLo
B2: Parameters | H2: D | I2: E | K2: S | L2: Cinv | M2: Cesf | N2: Ctot | P2: E[Cinv] | Q2: E[Cesf] | R2: E[Ctot] | S2: S
H3: =IF($B$8=0, EXP($C$13), _xlfn.LOGNORM.INV(RAND(), $C$13, $B$8)) -> 1.1571115 | I3: =IF($B$9=0, EXP($C$14), _xlfn.LOGNORM.INV(RAND(), $C$14, $B$9))*H3 -> 1.2147155 | K3: =$S$3 -> 1.3547706 | L3: =K3 -> 1.3547706 | M3: =$C$12*MAX(I3-K3,0) -> 0 | N3: =M3+L3 -> 1.3547706 | P3: =AVERAGE(L3:L1000) -> 1.3547706 | Q3: =AVERAGE(M3:M1000) -> 0.16549448 | R3: =AVERAGE(N3:N1000) -> 1.5202651 | S3: 1.3547706
B4: Uncertainty(standard deviation) | C4: No | D4: Low | E4: Med | F4: High | H4: =IF($B$8=0, EXP($C$13), _xlfn.LOGNORM.INV(RAND(), $C$13, $B$8)) -> 0.91271748 | I4: =IF($B$9=0, EXP($C$14), _xlfn.LOGNORM.INV(RAND(), $C$14, $B$9))*H4 -> 0.99584634 | K4: =$S$3 -> 1.3547706 | L4: =K4 -> 1.3547706 | M4: =$C$12*MAX(I4-K4,0) -> 0 | N4: =M4+L4 -> 1.3547706
C5: 0 | D5: 0.25 | E5: 0.5 | F5: 0.75 | H5: =IF($B$8=0, EXP($C$13), _xlfn.LOGNORM.INV(RAND(), $C$13, $B$8)) -> 0.91541545 | I5: =IF($B$9=0, EXP($C$14), _xlfn.LOGNORM.INV(RAND(), $C$14, $B$9))*H5 -> 0.86023765 | K5: =$S$3 -> 1.3547706 | L5: =K5 -> 1.3547706 | M5: =$C$12*MAX(I5-K5,0) -> 0 | N5: =M5+L5 -> 1.3547706
C6: 0 | D6: 0.25 | E6: 0.5 | F6: 0.75 | H6: =IF($B$8=0, EXP($C$13), _xlfn.LOGNORM.INV(RAND(), $C$13, $B$8)) -> 1.0652761 | I6: =IF($B$9=0, EXP($C$14), _xlfn.LOGNORM.INV(RAND(), $C$14, $B$9))*H6 -> 1.3926511 | K6: =$S$3 -> 1.3547706 | L6: =K6 -> 1.3547706 | M6: =$C$12*MAX(I6-K6,0) -> 0.075760955 | N6: =M6+L6 -> 1.4305316
H7: =IF($B$8=0, EXP($C$13), _xlfn.LOGNORM.INV(RAND(), $C$13, $B$8)) -> 1.1498335 | I7: =IF($B$9=0, EXP($C$14), _xlfn.LOGNORM.INV(RAND(), $C$14, $B$9))*H7 -> 1.2236585 | K7: =$S$3 -> 1.3547706 | L7: =K7 -> 1.3547706 | M7: =$C$12*MAX(I7-K7,0) -> 0 | N7: =M7+L7 -> 1.3547706
B8: =D5 -> 0.25 | C8: Current D uncertianty | H8: =IF($B$8=0, EXP($C$13), _xlfn.LOGNORM.INV(RAND(), $C$13, $B$8)) -> 1.0769516 | I8: =IF($B$9=0, EXP($C$14), _xlfn.LOGNORM.INV(RAND(), $C$14, $B$9))*H8 -> 1.4533948 | K8: =$S$3 -> 1.3547706 | L8: =K8 -> 1.3547706 | M8: =$C$12*MAX(I8-K8,0) -> 0.19724838 | N8: =M8+L8 -> 1.552019
B9: =D6 -> 0.25 | C9: Current E uncertainty | H9: =IF($B$8=0, EXP($C$13), _xlfn.LOGNORM.INV(RAND(), $C$13, $B$8)) -> 0.8624435 | I9: =IF($B$9=0, EXP($C$14), _xlfn.LOGNORM.INV(RAND(), $C$14, $B$9))*H9 -> 1.1005337 | K9: =$S$3 -> 1.3547706 | L9: =K9 -> 1.3547706 | M9: =$C$12*MAX(I9-K9,0) -> 0 | N9: =M9+L9 -> 1.3547706
H10: =IF($B$8=0, EXP($C$13), _xlfn.LOGNORM.INV(RAND(), $C$13, $B$8)) -> 1.0286065 | I10: =IF($B$9=0, EXP($C$14), _xlfn.LOGNORM.INV(RAND(), $C$14, $B$9))*H10 -> 1.2122524 | K10: =$S$3 -> 1.3547706 | L10: =K10 -> 1.3547706 | M10: =$C$12*MAX(I10-K10,0) -> 0 | N10: =M10+L10 -> 1.3547706
B11: Other parameters | H11: =IF($B$8=0, EXP($C$13), _xlfn.LOGNORM.INV(RAND(), $C$13, $B$8)) -> 0.6750811 | I11: =IF($B$9=0, EXP($C$14), _xlfn.LOGNORM.INV(RAND(), $C$14, $B$9))*H11 -> 0.57659815 | K11: =$S$3 -> 1.3547706 | L11: =K11 -> 1.3547706 | M11: =$C$12*MAX(I11-K11,0) -> 0 | N11: =M11+L11 -> 1.3547706
B12: c^s | C12: =Model!C12 -> 2 | H12: =IF($B$8=0, EXP($C$13), _xlfn.LOGNORM.INV(RAND(), $C$13, $B$8)) -> 0.84067518 | I12: =IF($B$9=0, EXP($C$14), _xlfn.LOGNORM.INV(RAND(), $C$14, $B$9))*H12 -> 0.83103433 | K12: =$S$3 -> 1.3547706 | L12: =K12 -> 1.3547706 | M12: =$C$12*MAX(I12-K12,0) -> 0 | N12: =M12+L12 -> 1.3547706
B13: Mean D | C13: =(-B8^2)/2 -> 0.03125 | H13: =IF($B$8=0, EXP($C$13), _xlfn.LOGNORM.INV(RAND(), $C$13, $B$8)) -> 1.1256742 | I13: =IF($B$9=0, EXP($C$14), _xlfn.LOGNORM.INV(RAND(), $C$14, $B$9))*H13 -> 0.84802887 | K13: =$S$3 -> 1.3547706 | L13: =K13 -> 1.3547706 | M13: =$C$12*MAX(I13-K13,0) -> 0 | N13: =M13+L13 -> 1.3547706
B14: Mean E | C14: =(-B9^2)/2 -> 0.03125 | H14: =IF($B$8=0, EXP($C$13), _xlfn.LOGNORM.INV(RAND(), $C$13, $B$8)) -> 0.65456479 | I14: =IF($B$9=0, EXP($C$14), _xlfn.LOGNORM.INV(RAND(), $C$14, $B$9))*H14 -> 0.73743646 | K14: =$S$3 -> 1.3547706 | L14: =K14 -> 1.3547706 | M14: =$C$12*MAX(I14-K14,0) -> 0 | N14: =M14+L14 -> 1.3547706
H15: =IF($B$8=0, EXP($C$13), _xlfn.LOGNORM.INV(RAND(), $C$13, $B$8)) -> 0.78395731 | I15: =IF($B$9=0, EXP($C$14), _xlfn.LOGNORM.INV(RAND(), $C$14, $B$9))*H15 -> 0.72304581 | K15: =$S$3 -> 1.3547706 | L15: =K15 -> 1.3547706 | M15: =$C$12*MAX(I15-K15,0) -> 0 | N15: =M15+L15 -> 1.3547706
H16: =IF($B$8=0, EXP($C$13), _xlfn.LOGNORM.INV(RAND(), $C$13, $B$8)) -> 0.99469084 | I16: =IF($B$9=0, EXP($C$14), _xlfn.LOGNORM.INV(RAND(), $C$14, $B$9))*H16 -> 1.0071161 | K16: =$S$3 -> 1.3547706 | L16: =K16 -> 1.3547706 | M16: =$C$12*MAX(I16-K16,0) -> 0 | N16: =M16+L16 -> 1.3547706
H17: =IF($B$8=0, EXP($C$13), _xlfn.LOGNORM.INV(RAND(), $C$13, $B$8)) -> 1.3758349 | I17: =IF($B$9=0, EXP($C$14), _xlfn.LOGNORM.INV(RAND(), $C$14, $B$9))*H17 -> 1.4646377 | K17: =$S$3 -> 1.3547706 | L17: =K17 -> 1.3547706 | M17: =$C$12*MAX(I17-K17,0) -> 0.21973412 | N17: =M17+L17 -> 1.5745047
H18: =IF($B$8=0, EXP($C$13), _xlfn.LOGNORM.INV(RAND(), $C$13, $B$8)) -> 1.5538435 | I18: =IF($B$9=0, EXP($C$14), _xlfn.LOGNORM.INV(RAND(), $C$14, $B$9))*H18 -> 1.1448372 | K18: =$S$3 -> 1.3547706 | L18: =K18 -> 1.3547706 | M18: =$C$12*MAX(I18-K18,0) -> 0 | N18: =M18+L18 -> 1.3547706
H19: =IF($B$8=0, EXP($C$13), _xlfn.LOGNORM.INV(RAND(), $C$13, $B$8)) -> 1.149754 | I19: =IF($B$9=0, EXP($C$14), _xlfn.LOGNORM.INV(RAND(), $C$14, $B$9))*H19 -> 1.3548877 | K19: =$S$3 -> 1.3547706 | L19: =K19 -> 1.3547706 | M19: =$C$12*MAX(I19-K19,0) -> 0.00023422428 | N19: =M19+L19 -> 1.3550048
H20: =IF($B$8=0, EXP($C$13), _xlfn.LOGNORM.INV(RAND(), $C$13, $B$8)) -> 0.90165141 | I20: =IF($B$9=0, EXP($C$14), _xlfn.LOGNORM.INV(RAND(), $C$14, $B$9))*H20 -> 0.63937944 | K20: =$S$3 -> 1.3547706 | L20: =K20 -> 1.3547706 | M20: =$C$12*MAX(I20-K20,0) -> 0 | N20: =M20+L20 -> 1.3547706
H21: =IF($B$8=0, EXP($C$13), _xlfn.LOGNORM.INV(RAND(), $C$13, $B$8)) -> 0.58786934 | I21: =IF($B$9=0, EXP($C$14), _xlfn.LOGNORM.INV(RAND(), $C$14, $B$9))*H21 -> 0.64505232 | K21: =$S$3 -> 1.3547706 | L21: =K21 -> 1.3547706 | M21: =$C$12*MAX(I21-K21,0) -> 0 | N21: =M21+L21 -> 1.3547706
H22: =IF($B$8=0, EXP($C$13), _xlfn.LOGNORM.INV(RAND(), $C$13, $B$8)) -> 0.60238438 | I22: =IF($B$9=0, EXP($C$14), _xlfn.LOGNORM.INV(RAND(), $C$14, $B$9))*H22 -> 0.41176838 | K22: =$S$3 -> 1.3547706 | L22: =K22 -> 1.3547706 | M22: =$C$12*MAX(I22-K22,0) -> 0 | N22: =M22+L22 -> 1.3547706
H23: =IF($B$8=0, EXP($C$13), _xlfn.LOGNORM.INV(RAND(), $C$13, $B$8)) -> 1.4506635 | I23: =IF($B$9=0, EXP($C$14), _xlfn.LOGNORM.INV(RAND(), $C$14, $B$9))*H23 -> 1.4120118 | K23: =$S$3 -> 1.3547706 | L23: =K23 -> 1.3547706 | M23: =$C$12*MAX(I23-K23,0) -> 0.11448241 | N23: =M23+L23 -> 1.469253
H24: =IF($B$8=0, EXP($C$13), _xlfn.LOGNORM.INV(RAND(), $C$13, $B$8)) -> 1.1931982 | I24: =IF($B$9=0, EXP($C$14), _xlfn.LOGNORM.INV(RAND(), $C$14, $B$9))*H24 -> 1.1095776 | K24: =$S$3 -> 1.3547706 | L24: =K24 -> 1.3547706 | M24: =$C$12*MAX(I24-K24,0) -> 0 | N24: =M24+L24 -> 1.3547706
